<robot name="3DOF-WORM">
    <link name="link-1">
        <visual>
            <origin xyz="0 0 0" rpy="-1.57 0 0"/>
            <geometry>
                <mesh filename="./link-1.gltf"/>
            </geometry>
        </visual>
    </link>

    <joint name="joint-1" type="revolute">
        <parent link="link-1"/>
        <child link="link-2"/>
        <origin xyz="0 0 0.1004" rpy="0 0 0" />
        <axis xyz="1 0 0" />
        <limit lower="-1.57" upper="1.57" effort="120" velocity="5.02654824"/>
        <dynamics damping="1"/>
    </joint>

    <link name="link-2">
        <visual>
            <origin xyz="-0.009 0 0" rpy="-1.57 0 0"/>
            <geometry>
                <mesh filename="./link-2.gltf"/>
            </geometry>
        </visual>
    </link>

    <joint name="joint-2" type="revolute">
        <parent link="link-2"/>
        <child link="link-3"/>
        <origin xyz="0 0 0.255" rpy="0 0 0" />
        <axis xyz="0 1 0" />
        <limit lower="-2.094" upper="2.094" effort="120" velocity="5.02654824"/>
        <dynamics damping="1"/>
    </joint>

    <link name="link-3">
        <visual>
            <origin xyz="0 -0.007 0" rpy="1.57 3.14 0"/>
            <geometry>
                <mesh filename="./link-3.gltf"/>
            </geometry>
        </visual>
    </link>

    <joint name="joint-3" type="revolute">
        <parent link="link-3"/>
        <child link="link-4"/>
        <origin xyz="0 0 0.22" rpy="0 0 0"/>
        <axis xyz="0 1 0" />
        <limit lower="-2.094" upper="2.094" effort="120" velocity="5.02654824"/>
        <dynamics damping="1"/>
    </joint>

    <link name="link-4">
        <visual>
            <origin xyz="0 0.015 0" rpy="-1.57 0 -1.57"/>
            <geometry>
                <mesh filename="./link-4.gltf"/>
            </geometry>
        </visual>
    </link>
</robot>