<?xml version="1.0" ?>
<!-- =================================================================================== -->
<!-- |    This document was autogenerated by xacro from xacro/hexapod.urdf.xacro       | -->
<!-- |    EDITING THIS FILE BY HAND IS NOT RECOMMENDED                                 | -->
<!-- =================================================================================== -->
<robot name="hexapod" xmlns:drake="http://drake.mit.edu">
  <!-- Virtual link to offset the body by some fixed amount -->
  <link name="virtual_hexapod_body"/>
  <joint name="virtual_hexapod_body_joint_fixed" type="fixed">
    <parent link="virtual_hexapod_body"/>
    <child link="hexapod_body"/>
    <origin xyz="0 0 1.35"/>
  </joint>
  <!-- Main pallet -->
  <link name="hexapod_body">
    <inertial>
      <origin rpy="0 0 -1.57" xyz="0 0 -0.064"/>
      <mass value="11.144"/>
      <inertia ixx="1.654" ixy="0" ixz="0" iyy="0.779" iyz="0" izz="2.362"/>
    </inertial>
    <visual>
      <origin rpy="0 0 -1.57" xyz="0 0 0"/>
      <geometry>
        <mesh filename="../meshes/gltf/hexapod-pallet.gltf"/>
      </geometry>
    </visual>
    <collision name="hexapod_front_left_collision">
      <origin rpy="0 0 0.959931" xyz="0.2 0.1 -0.064"/>
      <geometry>
        <box size="0.5 0.7 0.15"/>
      </geometry>
    </collision>
    <collision name="hexapod_front_right_collision">
      <origin rpy="0 0 -0.959931" xyz="0.2 -0.1 -0.064"/>
      <geometry>
        <box size="0.5 0.7 0.15"/>
      </geometry>
    </collision>
    <collision name="hexapod_back_left_collision">
      <origin rpy="0 0 -0.959931" xyz="-0.2 0.1 -0.064"/>
      <geometry>
        <box size="0.5 0.7 0.15"/>
      </geometry>
    </collision>
    <collision name="hexapod_back_right_collision">
      <origin rpy="0 0 0.959931" xyz="-0.2 -0.1 -0.064"/>
      <geometry>
        <box size="0.5 0.7 0.15"/>
      </geometry>
    </collision>
  </link>
  <!-- Front UIBs -->
  <joint name="front_left_uib_joint_fixed" type="fixed">
    <parent link="hexapod_body"/>
    <child link="front_left_uib"/>
    <origin rpy="-1.57 1.57 0" xyz="0.6 0.086 -0.064"/>
  </joint>
  <link name="front_left_uib"/>
  <joint name="front_right_uib_joint_fixed" type="fixed">
    <parent link="hexapod_body"/>
    <child link="front_right_uib"/>
    <origin rpy="1.57 -1.57 0" xyz="0.6 -0.086 -0.064"/>
  </joint>
  <link name="front_right_uib"/>
  <!-- Middle UIBs -->
  <joint name="middle_left_uib_joint_fixed" type="fixed">
    <parent link="hexapod_body"/>
    <child link="middle_left_uib"/>
    <origin rpy="-1.57 1.57 0" xyz="0 0.5 -0.064"/>
  </joint>
  <link name="middle_left_uib"/>
  <joint name="middle_right_uib_joint_fixed" type="fixed">
    <parent link="hexapod_body"/>
    <child link="middle_right_uib"/>
    <origin rpy="1.57 -1.57 0" xyz="0 -0.5 -0.064"/>
  </joint>
  <link name="middle_right_uib"/>
  <!-- Back UIBs -->
  <joint name="back_left_uib_joint_fixed" type="fixed">
    <parent link="hexapod_body"/>
    <child link="back_left_uib"/>
    <origin rpy="-1.57 1.57 0" xyz="-0.6 0.086 -0.064"/>
  </joint>
  <link name="back_left_uib"/>
  <joint name="back_right_uib_joint_fixed" type="fixed">
    <parent link="hexapod_body"/>
    <child link="back_right_uib"/>
    <origin rpy="1.57 -1.57 0" xyz="-0.6 -0.086 -0.064"/>
  </joint>
  <link name="back_right_uib"/>
  <joint name="duck_uib_joint_fixed" type="fixed">
    <parent link="front_left_uib"/>
    <child link="duck_base"/>
    <origin rpy="0 0 0" xyz="0 0 0"/>
  </joint>
  <link name="duck_base"/>
  <joint name="duck_base_joint_fixed" type="fixed">
    <parent link="duck_base"/>
    <child link="duck_link_0"/>
  </joint>
  <link name="duck_link_0">
    <inertial>
      <origin rpy="0 0 0" xyz="0 0 0.0725"/>
      <mass value="1.59"/>
      <inertia ixx="0.010" ixy="0" ixz="0" iyy="0.010" iyz="0" izz="0.011"/>
    </inertial>
    <visual>
      <origin rpy="0 0 0" xyz="0 0 0.045"/>
      <geometry>
        <mesh filename="../meshes/gltf/link-0.gltf"/>
      </geometry>
    </visual>
    <collision name="duck_link_0_base_collision">
      <origin rpy="0 0 0" xyz="0 0 0.035"/>
      <geometry>
        <cylinder length="0.11" radius="0.075"/>
      </geometry>
    </collision>
    <collision name="duck_link_0_motor_collision">
      <origin rpy="0 1.57 0" xyz="0.008 0 0.145"/>
      <geometry>
        <cylinder length="0.075" radius="0.06"/>
      </geometry>
    </collision>
  </link>
  <joint name="duck_joint_0" type="revolute">
    <parent link="duck_link_0"/>
    <child link="duck_link_1"/>
    <origin rpy="0 0 0" xyz="0 0 0.145"/>
    <axis xyz="1 0 0"/>
    <limit effort="120" lower="-2.094" upper="2.094" velocity="5.02654824"/>
    <dynamics damping="0.8487"/>
  </joint>
  <link name="duck_link_1">
    <inertial>
      <origin rpy="0 0 0" xyz="0 0 0.1275"/>
      <mass value="1.59"/>
      <inertia ixx="0.011" ixy="0" ixz="0" iyy="0.011" iyz="0" izz="0.004"/>
    </inertial>
    <visual>
      <origin rpy="0 0 -1.57" xyz="0.05 0 0"/>
      <geometry>
        <mesh filename="../meshes/gltf/link-1.gltf"/>
      </geometry>
    </visual>
    <collision name="duck_link_1_base_collision">
      <origin rpy="0 0 0" xyz="0.01 0 0.085"/>
      <geometry>
        <box size="0.1 0.08 0.22"/>
      </geometry>
    </collision>
    <collision name="duck_link_1_motor_collision">
      <origin rpy="1.57 0 0" xyz="0 -0.008 0.255"/>
      <geometry>
        <cylinder length="0.075" radius="0.06"/>
      </geometry>
    </collision>
  </link>
  <joint name="duck_joint_1" type="revolute">
    <parent link="duck_link_1"/>
    <child link="duck_link_2"/>
    <origin rpy="0 0 0" xyz="0 0 0.25"/>
    <axis xyz="0 1 0"/>
    <limit effort="120" lower="-2.094" upper="2.094" velocity="5.02654824"/>
    <dynamics damping="0.8487"/>
  </joint>
  <link name="duck_link_2">
    <inertial>
      <origin rpy="0 0 0" xyz="0 0 0.11"/>
      <mass value="1.59"/>
      <inertia ixx="0.009" ixy="0" ixz="0" iyy="0.009" iyz="0" izz="0.004"/>
    </inertial>
    <visual>
      <origin rpy="0 0 3.14" xyz="0 -0.05 0"/>
      <geometry>
        <mesh filename="../meshes/gltf/link-2.gltf"/>
      </geometry>
    </visual>
    <collision name="duck_link_2_base_collision">
      <origin rpy="0 0 0" xyz="0 -0.01 0.07"/>
      <geometry>
        <box size="0.08 0.1 0.18"/>
      </geometry>
    </collision>
    <collision name="duck_link_2_motor_collision">
      <origin rpy="1.57 0 0" xyz="0 -0.01 0.22"/>
      <geometry>
        <cylinder length="0.075" radius="0.06"/>
      </geometry>
    </collision>
  </link>
  <joint name="duck_joint_2" type="revolute">
    <parent link="duck_link_2"/>
    <child link="duck_link_3"/>
    <origin rpy="0 0 0" xyz="0 0 0.22"/>
    <axis xyz="0 1 0"/>
    <limit effort="120" lower="-2.094" upper="2.094" velocity="5.02654824"/>
    <dynamics damping="0.8487"/>
  </joint>
  <link name="duck_link_3">
    <inertial>
      <origin rpy="0 0 0" xyz="0 0.015 0.2425"/>
      <mass value="5.00"/>
      <inertia ixx="0.107" ixy="0" ixz="0" iyy="0.103" iyz="0" izz="0.014"/>
    </inertial>
    <visual>
      <origin rpy="0 0 1.57" xyz="0 -0.05 0"/>
      <geometry>
        <mesh filename="../meshes/gltf/link-3.gltf"/>
      </geometry>
    </visual>
    <collision name="duck_link_3_base_collision">
      <origin rpy="0 0 0" xyz="0 -0.015 0.2"/>
      <geometry>
        <box size="0.11 0.15 0.45"/>
      </geometry>
    </collision>
    <collision name="duck_link_3_uib_collision">
      <origin rpy="0 0 0" xyz="0 -0.01 0.46"/>
      <geometry>
        <cylinder length="0.08" radius="0.075"/>
      </geometry>
    </collision>
  </link>
  <!-- Downstream link -->
  <joint name="duck_end_uib_joint_fixed" type="fixed">
    <parent link="duck_link_3"/>
    <child link="duck_end_uib"/>
    <origin rpy="3.14 0 -0.35" xyz="0 -0.012 0.498"/>
  </joint>
  <link name="duck_end_uib"/>
  <!-- Transmission definitions -->
  <transmission name="duck_tran_0">
    <type>transmission_interface/SimpleTransmission</type>
    <joint name="duck_joint_0">
      <hardwareInterface>EffortJointInterface</hardwareInterface>
    </joint>
    <actuator name="duck_actuator_0">
      <mechanicalReduction>1</mechanicalReduction>
      <drake:gear_ratio value="64"/>
      <drake:rotor_inertia value="5.645e-05"/>
    </actuator>
  </transmission>
  <transmission name="duck_tran_1">
    <type>transmission_interface/SimpleTransmission</type>
    <joint name="duck_joint_1">
      <hardwareInterface>EffortJointInterface</hardwareInterface>
    </joint>
    <actuator name="duck_actuator_1">
      <mechanicalReduction>1</mechanicalReduction>
      <drake:gear_ratio value="64"/>
      <drake:rotor_inertia value="5.645e-05"/>
    </actuator>
  </transmission>
  <transmission name="duck_tran_2">
    <type>transmission_interface/SimpleTransmission</type>
    <joint name="duck_joint_2">
      <hardwareInterface>EffortJointInterface</hardwareInterface>
    </joint>
    <actuator name="duck_actuator_2">
      <mechanicalReduction>1</mechanicalReduction>
      <drake:gear_ratio value="64"/>
      <drake:rotor_inertia value="5.645e-05"/>
    </actuator>
  </transmission>
  <joint name="frog_uib_joint_fixed" type="fixed">
    <parent link="front_right_uib"/>
    <child link="frog_base"/>
    <origin rpy="0 0 0" xyz="0 0 0"/>
  </joint>
  <link name="frog_base"/>
  <joint name="frog_base_joint_fixed" type="fixed">
    <parent link="frog_base"/>
    <child link="frog_link_0"/>
  </joint>
  <link name="frog_link_0">
    <inertial>
      <origin rpy="0 0 0" xyz="0 0 0.0725"/>
      <mass value="1.59"/>
      <inertia ixx="0.010" ixy="0" ixz="0" iyy="0.010" iyz="0" izz="0.011"/>
    </inertial>
    <visual>
      <origin rpy="0 0 0" xyz="0 0 0.045"/>
      <geometry>
        <mesh filename="../meshes/gltf/link-0.gltf"/>
      </geometry>
    </visual>
    <collision name="frog_link_0_base_collision">
      <origin rpy="0 0 0" xyz="0 0 0.035"/>
      <geometry>
        <cylinder length="0.11" radius="0.075"/>
      </geometry>
    </collision>
    <collision name="frog_link_0_motor_collision">
      <origin rpy="0 1.57 0" xyz="0.008 0 0.145"/>
      <geometry>
        <cylinder length="0.075" radius="0.06"/>
      </geometry>
    </collision>
  </link>
  <joint name="frog_joint_0" type="revolute">
    <parent link="frog_link_0"/>
    <child link="frog_link_1"/>
    <origin rpy="0 0 0" xyz="0 0 0.145"/>
    <axis xyz="1 0 0"/>
    <limit effort="120" lower="-2.094" upper="2.094" velocity="5.02654824"/>
    <dynamics damping="0.8487"/>
  </joint>
  <link name="frog_link_1">
    <inertial>
      <origin rpy="0 0 0" xyz="0 0 0.1275"/>
      <mass value="1.59"/>
      <inertia ixx="0.011" ixy="0" ixz="0" iyy="0.011" iyz="0" izz="0.004"/>
    </inertial>
    <visual>
      <origin rpy="0 0 -1.57" xyz="0.05 0 0"/>
      <geometry>
        <mesh filename="../meshes/gltf/link-1.gltf"/>
      </geometry>
    </visual>
    <collision name="frog_link_1_base_collision">
      <origin rpy="0 0 0" xyz="0.01 0 0.085"/>
      <geometry>
        <box size="0.1 0.08 0.22"/>
      </geometry>
    </collision>
    <collision name="frog_link_1_motor_collision">
      <origin rpy="1.57 0 0" xyz="0 -0.008 0.255"/>
      <geometry>
        <cylinder length="0.075" radius="0.06"/>
      </geometry>
    </collision>
  </link>
  <joint name="frog_joint_1" type="revolute">
    <parent link="frog_link_1"/>
    <child link="frog_link_2"/>
    <origin rpy="0 0 0" xyz="0 0 0.25"/>
    <axis xyz="0 1 0"/>
    <limit effort="120" lower="-2.094" upper="2.094" velocity="5.02654824"/>
    <dynamics damping="0.8487"/>
  </joint>
  <link name="frog_link_2">
    <inertial>
      <origin rpy="0 0 0" xyz="0 0 0.11"/>
      <mass value="1.59"/>
      <inertia ixx="0.009" ixy="0" ixz="0" iyy="0.009" iyz="0" izz="0.004"/>
    </inertial>
    <visual>
      <origin rpy="0 0 3.14" xyz="0 -0.05 0"/>
      <geometry>
        <mesh filename="../meshes/gltf/link-2.gltf"/>
      </geometry>
    </visual>
    <collision name="frog_link_2_base_collision">
      <origin rpy="0 0 0" xyz="0 -0.01 0.07"/>
      <geometry>
        <box size="0.08 0.1 0.18"/>
      </geometry>
    </collision>
    <collision name="frog_link_2_motor_collision">
      <origin rpy="1.57 0 0" xyz="0 -0.01 0.22"/>
      <geometry>
        <cylinder length="0.075" radius="0.06"/>
      </geometry>
    </collision>
  </link>
  <joint name="frog_joint_2" type="revolute">
    <parent link="frog_link_2"/>
    <child link="frog_link_3"/>
    <origin rpy="0 0 0" xyz="0 0 0.22"/>
    <axis xyz="0 1 0"/>
    <limit effort="120" lower="-2.094" upper="2.094" velocity="5.02654824"/>
    <dynamics damping="0.8487"/>
  </joint>
  <link name="frog_link_3">
    <inertial>
      <origin rpy="0 0 0" xyz="0 0.015 0.2425"/>
      <mass value="5.00"/>
      <inertia ixx="0.107" ixy="0" ixz="0" iyy="0.103" iyz="0" izz="0.014"/>
    </inertial>
    <visual>
      <origin rpy="0 0 1.57" xyz="0 -0.05 0"/>
      <geometry>
        <mesh filename="../meshes/gltf/link-3.gltf"/>
      </geometry>
    </visual>
    <collision name="frog_link_3_base_collision">
      <origin rpy="0 0 0" xyz="0 -0.015 0.2"/>
      <geometry>
        <box size="0.11 0.15 0.45"/>
      </geometry>
    </collision>
    <collision name="frog_link_3_uib_collision">
      <origin rpy="0 0 0" xyz="0 -0.01 0.46"/>
      <geometry>
        <cylinder length="0.08" radius="0.075"/>
      </geometry>
    </collision>
  </link>
  <!-- Downstream link -->
  <joint name="frog_end_uib_joint_fixed" type="fixed">
    <parent link="frog_link_3"/>
    <child link="frog_end_uib"/>
    <origin rpy="3.14 0 -0.35" xyz="0 -0.012 0.498"/>
  </joint>
  <link name="frog_end_uib"/>
  <!-- Transmission definitions -->
  <transmission name="frog_tran_0">
    <type>transmission_interface/SimpleTransmission</type>
    <joint name="frog_joint_0">
      <hardwareInterface>EffortJointInterface</hardwareInterface>
    </joint>
    <actuator name="frog_actuator_0">
      <mechanicalReduction>1</mechanicalReduction>
      <drake:gear_ratio value="64"/>
      <drake:rotor_inertia value="5.645e-05"/>
    </actuator>
  </transmission>
  <transmission name="frog_tran_1">
    <type>transmission_interface/SimpleTransmission</type>
    <joint name="frog_joint_1">
      <hardwareInterface>EffortJointInterface</hardwareInterface>
    </joint>
    <actuator name="frog_actuator_1">
      <mechanicalReduction>1</mechanicalReduction>
      <drake:gear_ratio value="64"/>
      <drake:rotor_inertia value="5.645e-05"/>
    </actuator>
  </transmission>
  <transmission name="frog_tran_2">
    <type>transmission_interface/SimpleTransmission</type>
    <joint name="frog_joint_2">
      <hardwareInterface>EffortJointInterface</hardwareInterface>
    </joint>
    <actuator name="frog_actuator_2">
      <mechanicalReduction>1</mechanicalReduction>
      <drake:gear_ratio value="64"/>
      <drake:rotor_inertia value="5.645e-05"/>
    </actuator>
  </transmission>
  <joint name="seal_uib_joint_fixed" type="fixed">
    <parent link="middle_left_uib"/>
    <child link="seal_base"/>
    <origin rpy="0 0 0" xyz="0 0 0"/>
  </joint>
  <link name="seal_base"/>
  <joint name="seal_base_joint_fixed" type="fixed">
    <parent link="seal_base"/>
    <child link="seal_link_0"/>
  </joint>
  <link name="seal_link_0">
    <inertial>
      <origin rpy="0 0 0" xyz="0 0 0.0725"/>
      <mass value="1.59"/>
      <inertia ixx="0.010" ixy="0" ixz="0" iyy="0.010" iyz="0" izz="0.011"/>
    </inertial>
    <visual>
      <origin rpy="0 0 0" xyz="0 0 0.045"/>
      <geometry>
        <mesh filename="../meshes/gltf/link-0.gltf"/>
      </geometry>
    </visual>
    <collision name="seal_link_0_base_collision">
      <origin rpy="0 0 0" xyz="0 0 0.035"/>
      <geometry>
        <cylinder length="0.11" radius="0.075"/>
      </geometry>
    </collision>
    <collision name="seal_link_0_motor_collision">
      <origin rpy="0 1.57 0" xyz="0.008 0 0.145"/>
      <geometry>
        <cylinder length="0.075" radius="0.06"/>
      </geometry>
    </collision>
  </link>
  <joint name="seal_joint_0" type="revolute">
    <parent link="seal_link_0"/>
    <child link="seal_link_1"/>
    <origin rpy="0 0 0" xyz="0 0 0.145"/>
    <axis xyz="1 0 0"/>
    <limit effort="120" lower="-2.094" upper="2.094" velocity="5.02654824"/>
    <dynamics damping="0.8487"/>
  </joint>
  <link name="seal_link_1">
    <inertial>
      <origin rpy="0 0 0" xyz="0 0 0.1275"/>
      <mass value="1.59"/>
      <inertia ixx="0.011" ixy="0" ixz="0" iyy="0.011" iyz="0" izz="0.004"/>
    </inertial>
    <visual>
      <origin rpy="0 0 -1.57" xyz="0.05 0 0"/>
      <geometry>
        <mesh filename="../meshes/gltf/link-1.gltf"/>
      </geometry>
    </visual>
    <collision name="seal_link_1_base_collision">
      <origin rpy="0 0 0" xyz="0.01 0 0.085"/>
      <geometry>
        <box size="0.1 0.08 0.22"/>
      </geometry>
    </collision>
    <collision name="seal_link_1_motor_collision">
      <origin rpy="1.57 0 0" xyz="0 -0.008 0.255"/>
      <geometry>
        <cylinder length="0.075" radius="0.06"/>
      </geometry>
    </collision>
  </link>
  <joint name="seal_joint_1" type="revolute">
    <parent link="seal_link_1"/>
    <child link="seal_link_2"/>
    <origin rpy="0 0 0" xyz="0 0 0.25"/>
    <axis xyz="0 1 0"/>
    <limit effort="120" lower="-2.094" upper="2.094" velocity="5.02654824"/>
    <dynamics damping="0.8487"/>
  </joint>
  <link name="seal_link_2">
    <inertial>
      <origin rpy="0 0 0" xyz="0 0 0.11"/>
      <mass value="1.59"/>
      <inertia ixx="0.009" ixy="0" ixz="0" iyy="0.009" iyz="0" izz="0.004"/>
    </inertial>
    <visual>
      <origin rpy="0 0 3.14" xyz="0 -0.05 0"/>
      <geometry>
        <mesh filename="../meshes/gltf/link-2.gltf"/>
      </geometry>
    </visual>
    <collision name="seal_link_2_base_collision">
      <origin rpy="0 0 0" xyz="0 -0.01 0.07"/>
      <geometry>
        <box size="0.08 0.1 0.18"/>
      </geometry>
    </collision>
    <collision name="seal_link_2_motor_collision">
      <origin rpy="1.57 0 0" xyz="0 -0.01 0.22"/>
      <geometry>
        <cylinder length="0.075" radius="0.06"/>
      </geometry>
    </collision>
  </link>
  <joint name="seal_joint_2" type="revolute">
    <parent link="seal_link_2"/>
    <child link="seal_link_3"/>
    <origin rpy="0 0 0" xyz="0 0 0.22"/>
    <axis xyz="0 1 0"/>
    <limit effort="120" lower="-2.094" upper="2.094" velocity="5.02654824"/>
    <dynamics damping="0.8487"/>
  </joint>
  <link name="seal_link_3">
    <inertial>
      <origin rpy="0 0 0" xyz="0 0.015 0.2425"/>
      <mass value="5.00"/>
      <inertia ixx="0.107" ixy="0" ixz="0" iyy="0.103" iyz="0" izz="0.014"/>
    </inertial>
    <visual>
      <origin rpy="0 0 1.57" xyz="0 -0.05 0"/>
      <geometry>
        <mesh filename="../meshes/gltf/link-3.gltf"/>
      </geometry>
    </visual>
    <collision name="seal_link_3_base_collision">
      <origin rpy="0 0 0" xyz="0 -0.015 0.2"/>
      <geometry>
        <box size="0.11 0.15 0.45"/>
      </geometry>
    </collision>
    <collision name="seal_link_3_uib_collision">
      <origin rpy="0 0 0" xyz="0 -0.01 0.46"/>
      <geometry>
        <cylinder length="0.08" radius="0.075"/>
      </geometry>
    </collision>
  </link>
  <!-- Downstream link -->
  <joint name="seal_end_uib_joint_fixed" type="fixed">
    <parent link="seal_link_3"/>
    <child link="seal_end_uib"/>
    <origin rpy="3.14 0 -0.35" xyz="0 -0.012 0.498"/>
  </joint>
  <link name="seal_end_uib"/>
  <!-- Transmission definitions -->
  <transmission name="seal_tran_0">
    <type>transmission_interface/SimpleTransmission</type>
    <joint name="seal_joint_0">
      <hardwareInterface>EffortJointInterface</hardwareInterface>
    </joint>
    <actuator name="seal_actuator_0">
      <mechanicalReduction>1</mechanicalReduction>
      <drake:gear_ratio value="64"/>
      <drake:rotor_inertia value="5.645e-05"/>
    </actuator>
  </transmission>
  <transmission name="seal_tran_1">
    <type>transmission_interface/SimpleTransmission</type>
    <joint name="seal_joint_1">
      <hardwareInterface>EffortJointInterface</hardwareInterface>
    </joint>
    <actuator name="seal_actuator_1">
      <mechanicalReduction>1</mechanicalReduction>
      <drake:gear_ratio value="64"/>
      <drake:rotor_inertia value="5.645e-05"/>
    </actuator>
  </transmission>
  <transmission name="seal_tran_2">
    <type>transmission_interface/SimpleTransmission</type>
    <joint name="seal_joint_2">
      <hardwareInterface>EffortJointInterface</hardwareInterface>
    </joint>
    <actuator name="seal_actuator_2">
      <mechanicalReduction>1</mechanicalReduction>
      <drake:gear_ratio value="64"/>
      <drake:rotor_inertia value="5.645e-05"/>
    </actuator>
  </transmission>
  <joint name="hare_uib_joint_fixed" type="fixed">
    <parent link="middle_right_uib"/>
    <child link="hare_base"/>
    <origin rpy="0 0 0" xyz="0 0 0"/>
  </joint>
  <link name="hare_base"/>
  <joint name="hare_base_joint_fixed" type="fixed">
    <parent link="hare_base"/>
    <child link="hare_link_0"/>
  </joint>
  <link name="hare_link_0">
    <inertial>
      <origin rpy="0 0 0" xyz="0 0 0.0725"/>
      <mass value="1.59"/>
      <inertia ixx="0.010" ixy="0" ixz="0" iyy="0.010" iyz="0" izz="0.011"/>
    </inertial>
    <visual>
      <origin rpy="0 0 0" xyz="0 0 0.045"/>
      <geometry>
        <mesh filename="../meshes/gltf/link-0.gltf"/>
      </geometry>
    </visual>
    <collision name="hare_link_0_base_collision">
      <origin rpy="0 0 0" xyz="0 0 0.035"/>
      <geometry>
        <cylinder length="0.11" radius="0.075"/>
      </geometry>
    </collision>
    <collision name="hare_link_0_motor_collision">
      <origin rpy="0 1.57 0" xyz="0.008 0 0.145"/>
      <geometry>
        <cylinder length="0.075" radius="0.06"/>
      </geometry>
    </collision>
  </link>
  <joint name="hare_joint_0" type="revolute">
    <parent link="hare_link_0"/>
    <child link="hare_link_1"/>
    <origin rpy="0 0 0" xyz="0 0 0.145"/>
    <axis xyz="1 0 0"/>
    <limit effort="120" lower="-2.094" upper="2.094" velocity="5.02654824"/>
    <dynamics damping="0.8487"/>
  </joint>
  <link name="hare_link_1">
    <inertial>
      <origin rpy="0 0 0" xyz="0 0 0.1275"/>
      <mass value="1.59"/>
      <inertia ixx="0.011" ixy="0" ixz="0" iyy="0.011" iyz="0" izz="0.004"/>
    </inertial>
    <visual>
      <origin rpy="0 0 -1.57" xyz="0.05 0 0"/>
      <geometry>
        <mesh filename="../meshes/gltf/link-1.gltf"/>
      </geometry>
    </visual>
    <collision name="hare_link_1_base_collision">
      <origin rpy="0 0 0" xyz="0.01 0 0.085"/>
      <geometry>
        <box size="0.1 0.08 0.22"/>
      </geometry>
    </collision>
    <collision name="hare_link_1_motor_collision">
      <origin rpy="1.57 0 0" xyz="0 -0.008 0.255"/>
      <geometry>
        <cylinder length="0.075" radius="0.06"/>
      </geometry>
    </collision>
  </link>
  <joint name="hare_joint_1" type="revolute">
    <parent link="hare_link_1"/>
    <child link="hare_link_2"/>
    <origin rpy="0 0 0" xyz="0 0 0.25"/>
    <axis xyz="0 1 0"/>
    <limit effort="120" lower="-2.094" upper="2.094" velocity="5.02654824"/>
    <dynamics damping="0.8487"/>
  </joint>
  <link name="hare_link_2">
    <inertial>
      <origin rpy="0 0 0" xyz="0 0 0.11"/>
      <mass value="1.59"/>
      <inertia ixx="0.009" ixy="0" ixz="0" iyy="0.009" iyz="0" izz="0.004"/>
    </inertial>
    <visual>
      <origin rpy="0 0 3.14" xyz="0 -0.05 0"/>
      <geometry>
        <mesh filename="../meshes/gltf/link-2.gltf"/>
      </geometry>
    </visual>
    <collision name="hare_link_2_base_collision">
      <origin rpy="0 0 0" xyz="0 -0.01 0.07"/>
      <geometry>
        <box size="0.08 0.1 0.18"/>
      </geometry>
    </collision>
    <collision name="hare_link_2_motor_collision">
      <origin rpy="1.57 0 0" xyz="0 -0.01 0.22"/>
      <geometry>
        <cylinder length="0.075" radius="0.06"/>
      </geometry>
    </collision>
  </link>
  <joint name="hare_joint_2" type="revolute">
    <parent link="hare_link_2"/>
    <child link="hare_link_3"/>
    <origin rpy="0 0 0" xyz="0 0 0.22"/>
    <axis xyz="0 1 0"/>
    <limit effort="120" lower="-2.094" upper="2.094" velocity="5.02654824"/>
    <dynamics damping="0.8487"/>
  </joint>
  <link name="hare_link_3">
    <inertial>
      <origin rpy="0 0 0" xyz="0 0.015 0.2425"/>
      <mass value="5.00"/>
      <inertia ixx="0.107" ixy="0" ixz="0" iyy="0.103" iyz="0" izz="0.014"/>
    </inertial>
    <visual>
      <origin rpy="0 0 1.57" xyz="0 -0.05 0"/>
      <geometry>
        <mesh filename="../meshes/gltf/link-3.gltf"/>
      </geometry>
    </visual>
    <collision name="hare_link_3_base_collision">
      <origin rpy="0 0 0" xyz="0 -0.015 0.2"/>
      <geometry>
        <box size="0.11 0.15 0.45"/>
      </geometry>
    </collision>
    <collision name="hare_link_3_uib_collision">
      <origin rpy="0 0 0" xyz="0 -0.01 0.46"/>
      <geometry>
        <cylinder length="0.08" radius="0.075"/>
      </geometry>
    </collision>
  </link>
  <!-- Downstream link -->
  <joint name="hare_end_uib_joint_fixed" type="fixed">
    <parent link="hare_link_3"/>
    <child link="hare_end_uib"/>
    <origin rpy="3.14 0 -0.35" xyz="0 -0.012 0.498"/>
  </joint>
  <link name="hare_end_uib"/>
  <!-- Transmission definitions -->
  <transmission name="hare_tran_0">
    <type>transmission_interface/SimpleTransmission</type>
    <joint name="hare_joint_0">
      <hardwareInterface>EffortJointInterface</hardwareInterface>
    </joint>
    <actuator name="hare_actuator_0">
      <mechanicalReduction>1</mechanicalReduction>
      <drake:gear_ratio value="64"/>
      <drake:rotor_inertia value="5.645e-05"/>
    </actuator>
  </transmission>
  <transmission name="hare_tran_1">
    <type>transmission_interface/SimpleTransmission</type>
    <joint name="hare_joint_1">
      <hardwareInterface>EffortJointInterface</hardwareInterface>
    </joint>
    <actuator name="hare_actuator_1">
      <mechanicalReduction>1</mechanicalReduction>
      <drake:gear_ratio value="64"/>
      <drake:rotor_inertia value="5.645e-05"/>
    </actuator>
  </transmission>
  <transmission name="hare_tran_2">
    <type>transmission_interface/SimpleTransmission</type>
    <joint name="hare_joint_2">
      <hardwareInterface>EffortJointInterface</hardwareInterface>
    </joint>
    <actuator name="hare_actuator_2">
      <mechanicalReduction>1</mechanicalReduction>
      <drake:gear_ratio value="64"/>
      <drake:rotor_inertia value="5.645e-05"/>
    </actuator>
  </transmission>
  <joint name="lion_uib_joint_fixed" type="fixed">
    <parent link="back_left_uib"/>
    <child link="lion_base"/>
    <origin rpy="0 0 0" xyz="0 0 0"/>
  </joint>
  <link name="lion_base"/>
  <joint name="lion_base_joint_fixed" type="fixed">
    <parent link="lion_base"/>
    <child link="lion_link_0"/>
  </joint>
  <link name="lion_link_0">
    <inertial>
      <origin rpy="0 0 0" xyz="0 0 0.0725"/>
      <mass value="1.59"/>
      <inertia ixx="0.010" ixy="0" ixz="0" iyy="0.010" iyz="0" izz="0.011"/>
    </inertial>
    <visual>
      <origin rpy="0 0 0" xyz="0 0 0.045"/>
      <geometry>
        <mesh filename="../meshes/gltf/link-0.gltf"/>
      </geometry>
    </visual>
    <collision name="lion_link_0_base_collision">
      <origin rpy="0 0 0" xyz="0 0 0.035"/>
      <geometry>
        <cylinder length="0.11" radius="0.075"/>
      </geometry>
    </collision>
    <collision name="lion_link_0_motor_collision">
      <origin rpy="0 1.57 0" xyz="0.008 0 0.145"/>
      <geometry>
        <cylinder length="0.075" radius="0.06"/>
      </geometry>
    </collision>
  </link>
  <joint name="lion_joint_0" type="revolute">
    <parent link="lion_link_0"/>
    <child link="lion_link_1"/>
    <origin rpy="0 0 0" xyz="0 0 0.145"/>
    <axis xyz="1 0 0"/>
    <limit effort="120" lower="-2.094" upper="2.094" velocity="5.02654824"/>
    <dynamics damping="0.8487"/>
  </joint>
  <link name="lion_link_1">
    <inertial>
      <origin rpy="0 0 0" xyz="0 0 0.1275"/>
      <mass value="1.59"/>
      <inertia ixx="0.011" ixy="0" ixz="0" iyy="0.011" iyz="0" izz="0.004"/>
    </inertial>
    <visual>
      <origin rpy="0 0 -1.57" xyz="0.05 0 0"/>
      <geometry>
        <mesh filename="../meshes/gltf/link-1.gltf"/>
      </geometry>
    </visual>
    <collision name="lion_link_1_base_collision">
      <origin rpy="0 0 0" xyz="0.01 0 0.085"/>
      <geometry>
        <box size="0.1 0.08 0.22"/>
      </geometry>
    </collision>
    <collision name="lion_link_1_motor_collision">
      <origin rpy="1.57 0 0" xyz="0 -0.008 0.255"/>
      <geometry>
        <cylinder length="0.075" radius="0.06"/>
      </geometry>
    </collision>
  </link>
  <joint name="lion_joint_1" type="revolute">
    <parent link="lion_link_1"/>
    <child link="lion_link_2"/>
    <origin rpy="0 0 0" xyz="0 0 0.25"/>
    <axis xyz="0 1 0"/>
    <limit effort="120" lower="-2.094" upper="2.094" velocity="5.02654824"/>
    <dynamics damping="0.8487"/>
  </joint>
  <link name="lion_link_2">
    <inertial>
      <origin rpy="0 0 0" xyz="0 0 0.11"/>
      <mass value="1.59"/>
      <inertia ixx="0.009" ixy="0" ixz="0" iyy="0.009" iyz="0" izz="0.004"/>
    </inertial>
    <visual>
      <origin rpy="0 0 3.14" xyz="0 -0.05 0"/>
      <geometry>
        <mesh filename="../meshes/gltf/link-2.gltf"/>
      </geometry>
    </visual>
    <collision name="lion_link_2_base_collision">
      <origin rpy="0 0 0" xyz="0 -0.01 0.07"/>
      <geometry>
        <box size="0.08 0.1 0.18"/>
      </geometry>
    </collision>
    <collision name="lion_link_2_motor_collision">
      <origin rpy="1.57 0 0" xyz="0 -0.01 0.22"/>
      <geometry>
        <cylinder length="0.075" radius="0.06"/>
      </geometry>
    </collision>
  </link>
  <joint name="lion_joint_2" type="revolute">
    <parent link="lion_link_2"/>
    <child link="lion_link_3"/>
    <origin rpy="0 0 0" xyz="0 0 0.22"/>
    <axis xyz="0 1 0"/>
    <limit effort="120" lower="-2.094" upper="2.094" velocity="5.02654824"/>
    <dynamics damping="0.8487"/>
  </joint>
  <link name="lion_link_3">
    <inertial>
      <origin rpy="0 0 0" xyz="0 0.015 0.2425"/>
      <mass value="5.00"/>
      <inertia ixx="0.107" ixy="0" ixz="0" iyy="0.103" iyz="0" izz="0.014"/>
    </inertial>
    <visual>
      <origin rpy="0 0 1.57" xyz="0 -0.05 0"/>
      <geometry>
        <mesh filename="../meshes/gltf/link-3.gltf"/>
      </geometry>
    </visual>
    <collision name="lion_link_3_base_collision">
      <origin rpy="0 0 0" xyz="0 -0.015 0.2"/>
      <geometry>
        <box size="0.11 0.15 0.45"/>
      </geometry>
    </collision>
    <collision name="lion_link_3_uib_collision">
      <origin rpy="0 0 0" xyz="0 -0.01 0.46"/>
      <geometry>
        <cylinder length="0.08" radius="0.075"/>
      </geometry>
    </collision>
  </link>
  <!-- Downstream link -->
  <joint name="lion_end_uib_joint_fixed" type="fixed">
    <parent link="lion_link_3"/>
    <child link="lion_end_uib"/>
    <origin rpy="3.14 0 -0.35" xyz="0 -0.012 0.498"/>
  </joint>
  <link name="lion_end_uib"/>
  <!-- Transmission definitions -->
  <transmission name="lion_tran_0">
    <type>transmission_interface/SimpleTransmission</type>
    <joint name="lion_joint_0">
      <hardwareInterface>EffortJointInterface</hardwareInterface>
    </joint>
    <actuator name="lion_actuator_0">
      <mechanicalReduction>1</mechanicalReduction>
      <drake:gear_ratio value="64"/>
      <drake:rotor_inertia value="5.645e-05"/>
    </actuator>
  </transmission>
  <transmission name="lion_tran_1">
    <type>transmission_interface/SimpleTransmission</type>
    <joint name="lion_joint_1">
      <hardwareInterface>EffortJointInterface</hardwareInterface>
    </joint>
    <actuator name="lion_actuator_1">
      <mechanicalReduction>1</mechanicalReduction>
      <drake:gear_ratio value="64"/>
      <drake:rotor_inertia value="5.645e-05"/>
    </actuator>
  </transmission>
  <transmission name="lion_tran_2">
    <type>transmission_interface/SimpleTransmission</type>
    <joint name="lion_joint_2">
      <hardwareInterface>EffortJointInterface</hardwareInterface>
    </joint>
    <actuator name="lion_actuator_2">
      <mechanicalReduction>1</mechanicalReduction>
      <drake:gear_ratio value="64"/>
      <drake:rotor_inertia value="5.645e-05"/>
    </actuator>
  </transmission>
  <joint name="pony_uib_joint_fixed" type="fixed">
    <parent link="back_right_uib"/>
    <child link="pony_base"/>
    <origin rpy="0 0 0" xyz="0 0 0"/>
  </joint>
  <link name="pony_base"/>
  <joint name="pony_base_joint_fixed" type="fixed">
    <parent link="pony_base"/>
    <child link="pony_link_0"/>
  </joint>
  <link name="pony_link_0">
    <inertial>
      <origin rpy="0 0 0" xyz="0 0 0.0725"/>
      <mass value="1.59"/>
      <inertia ixx="0.010" ixy="0" ixz="0" iyy="0.010" iyz="0" izz="0.011"/>
    </inertial>
    <visual>
      <origin rpy="0 0 0" xyz="0 0 0.045"/>
      <geometry>
        <mesh filename="../meshes/gltf/link-0.gltf"/>
      </geometry>
    </visual>
    <collision name="pony_link_0_base_collision">
      <origin rpy="0 0 0" xyz="0 0 0.035"/>
      <geometry>
        <cylinder length="0.11" radius="0.075"/>
      </geometry>
    </collision>
    <collision name="pony_link_0_motor_collision">
      <origin rpy="0 1.57 0" xyz="0.008 0 0.145"/>
      <geometry>
        <cylinder length="0.075" radius="0.06"/>
      </geometry>
    </collision>
  </link>
  <joint name="pony_joint_0" type="revolute">
    <parent link="pony_link_0"/>
    <child link="pony_link_1"/>
    <origin rpy="0 0 0" xyz="0 0 0.145"/>
    <axis xyz="1 0 0"/>
    <limit effort="120" lower="-2.094" upper="2.094" velocity="5.02654824"/>
    <dynamics damping="0.8487"/>
  </joint>
  <link name="pony_link_1">
    <inertial>
      <origin rpy="0 0 0" xyz="0 0 0.1275"/>
      <mass value="1.59"/>
      <inertia ixx="0.011" ixy="0" ixz="0" iyy="0.011" iyz="0" izz="0.004"/>
    </inertial>
    <visual>
      <origin rpy="0 0 -1.57" xyz="0.05 0 0"/>
      <geometry>
        <mesh filename="../meshes/gltf/link-1.gltf"/>
      </geometry>
    </visual>
    <collision name="pony_link_1_base_collision">
      <origin rpy="0 0 0" xyz="0.01 0 0.085"/>
      <geometry>
        <box size="0.1 0.08 0.22"/>
      </geometry>
    </collision>
    <collision name="pony_link_1_motor_collision">
      <origin rpy="1.57 0 0" xyz="0 -0.008 0.255"/>
      <geometry>
        <cylinder length="0.075" radius="0.06"/>
      </geometry>
    </collision>
  </link>
  <joint name="pony_joint_1" type="revolute">
    <parent link="pony_link_1"/>
    <child link="pony_link_2"/>
    <origin rpy="0 0 0" xyz="0 0 0.25"/>
    <axis xyz="0 1 0"/>
    <limit effort="120" lower="-2.094" upper="2.094" velocity="5.02654824"/>
    <dynamics damping="0.8487"/>
  </joint>
  <link name="pony_link_2">
    <inertial>
      <origin rpy="0 0 0" xyz="0 0 0.11"/>
      <mass value="1.59"/>
      <inertia ixx="0.009" ixy="0" ixz="0" iyy="0.009" iyz="0" izz="0.004"/>
    </inertial>
    <visual>
      <origin rpy="0 0 3.14" xyz="0 -0.05 0"/>
      <geometry>
        <mesh filename="../meshes/gltf/link-2.gltf"/>
      </geometry>
    </visual>
    <collision name="pony_link_2_base_collision">
      <origin rpy="0 0 0" xyz="0 -0.01 0.07"/>
      <geometry>
        <box size="0.08 0.1 0.18"/>
      </geometry>
    </collision>
    <collision name="pony_link_2_motor_collision">
      <origin rpy="1.57 0 0" xyz="0 -0.01 0.22"/>
      <geometry>
        <cylinder length="0.075" radius="0.06"/>
      </geometry>
    </collision>
  </link>
  <joint name="pony_joint_2" type="revolute">
    <parent link="pony_link_2"/>
    <child link="pony_link_3"/>
    <origin rpy="0 0 0" xyz="0 0 0.22"/>
    <axis xyz="0 1 0"/>
    <limit effort="120" lower="-2.094" upper="2.094" velocity="5.02654824"/>
    <dynamics damping="0.8487"/>
  </joint>
  <link name="pony_link_3">
    <inertial>
      <origin rpy="0 0 0" xyz="0 0.015 0.2425"/>
      <mass value="5.00"/>
      <inertia ixx="0.107" ixy="0" ixz="0" iyy="0.103" iyz="0" izz="0.014"/>
    </inertial>
    <visual>
      <origin rpy="0 0 1.57" xyz="0 -0.05 0"/>
      <geometry>
        <mesh filename="../meshes/gltf/link-3.gltf"/>
      </geometry>
    </visual>
    <collision name="pony_link_3_base_collision">
      <origin rpy="0 0 0" xyz="0 -0.015 0.2"/>
      <geometry>
        <box size="0.11 0.15 0.45"/>
      </geometry>
    </collision>
    <collision name="pony_link_3_uib_collision">
      <origin rpy="0 0 0" xyz="0 -0.01 0.46"/>
      <geometry>
        <cylinder length="0.08" radius="0.075"/>
      </geometry>
    </collision>
  </link>
  <!-- Downstream link -->
  <joint name="pony_end_uib_joint_fixed" type="fixed">
    <parent link="pony_link_3"/>
    <child link="pony_end_uib"/>
    <origin rpy="3.14 0 -0.35" xyz="0 -0.012 0.498"/>
  </joint>
  <link name="pony_end_uib"/>
  <!-- Transmission definitions -->
  <transmission name="pony_tran_0">
    <type>transmission_interface/SimpleTransmission</type>
    <joint name="pony_joint_0">
      <hardwareInterface>EffortJointInterface</hardwareInterface>
    </joint>
    <actuator name="pony_actuator_0">
      <mechanicalReduction>1</mechanicalReduction>
      <drake:gear_ratio value="64"/>
      <drake:rotor_inertia value="5.645e-05"/>
    </actuator>
  </transmission>
  <transmission name="pony_tran_1">
    <type>transmission_interface/SimpleTransmission</type>
    <joint name="pony_joint_1">
      <hardwareInterface>EffortJointInterface</hardwareInterface>
    </joint>
    <actuator name="pony_actuator_1">
      <mechanicalReduction>1</mechanicalReduction>
      <drake:gear_ratio value="64"/>
      <drake:rotor_inertia value="5.645e-05"/>
    </actuator>
  </transmission>
  <transmission name="pony_tran_2">
    <type>transmission_interface/SimpleTransmission</type>
    <joint name="pony_joint_2">
      <hardwareInterface>EffortJointInterface</hardwareInterface>
    </joint>
    <actuator name="pony_actuator_2">
      <mechanicalReduction>1</mechanicalReduction>
      <drake:gear_ratio value="64"/>
      <drake:rotor_inertia value="5.645e-05"/>
    </actuator>
  </transmission>
  <joint name="duck_rubber_foot_joint_fixed" type="fixed">
    <parent link="duck_end_uib"/>
    <child link="duck_rubber_foot"/>
  </joint>
  <link name="duck_rubber_foot">
    <inertial>
      <origin xyz="0 0 -0.01"/>
      <mass value="1.54"/>
      <inertia ixx="0.004" ixy="0.0" ixz="0.0" iyy="0.004" iyz="0.0" izz="0.007"/>
    </inertial>
    <visual>
      <geometry>
        <mesh filename="../meshes/gltf/rubber-foot.gltf"/>
      </geometry>
    </visual>
    <collision name="duck_rubber_foot_uib_collision">
      <origin rpy="0 0 0" xyz="0 0 -0.01"/>
      <geometry>
        <cylinder length="0.05" radius="0.07"/>
      </geometry>
    </collision>
    <collision name="duck_rubber_foot_pad_collision">
      <origin rpy="0 0 0" xyz="0 0 -0.037"/>
      <geometry>
        <cylinder length="0.018" radius="0.115"/>
      </geometry>
    </collision>
  </link>
  <joint name="frog_rubber_foot_joint_fixed" type="fixed">
    <parent link="frog_end_uib"/>
    <child link="frog_rubber_foot"/>
  </joint>
  <link name="frog_rubber_foot">
    <inertial>
      <origin xyz="0 0 -0.01"/>
      <mass value="1.54"/>
      <inertia ixx="0.004" ixy="0.0" ixz="0.0" iyy="0.004" iyz="0.0" izz="0.007"/>
    </inertial>
    <visual>
      <geometry>
        <mesh filename="../meshes/gltf/rubber-foot.gltf"/>
      </geometry>
    </visual>
    <collision name="frog_rubber_foot_uib_collision">
      <origin rpy="0 0 0" xyz="0 0 -0.01"/>
      <geometry>
        <cylinder length="0.05" radius="0.07"/>
      </geometry>
    </collision>
    <collision name="frog_rubber_foot_pad_collision">
      <origin rpy="0 0 0" xyz="0 0 -0.037"/>
      <geometry>
        <cylinder length="0.018" radius="0.115"/>
      </geometry>
    </collision>
  </link>
  <joint name="seal_rubber_foot_joint_fixed" type="fixed">
    <parent link="seal_end_uib"/>
    <child link="seal_rubber_foot"/>
  </joint>
  <link name="seal_rubber_foot">
    <inertial>
      <origin xyz="0 0 -0.01"/>
      <mass value="1.54"/>
      <inertia ixx="0.004" ixy="0.0" ixz="0.0" iyy="0.004" iyz="0.0" izz="0.007"/>
    </inertial>
    <visual>
      <geometry>
        <mesh filename="../meshes/gltf/rubber-foot.gltf"/>
      </geometry>
    </visual>
    <collision name="seal_rubber_foot_uib_collision">
      <origin rpy="0 0 0" xyz="0 0 -0.01"/>
      <geometry>
        <cylinder length="0.05" radius="0.07"/>
      </geometry>
    </collision>
    <collision name="seal_rubber_foot_pad_collision">
      <origin rpy="0 0 0" xyz="0 0 -0.037"/>
      <geometry>
        <cylinder length="0.018" radius="0.115"/>
      </geometry>
    </collision>
  </link>
  <joint name="hare_rubber_foot_joint_fixed" type="fixed">
    <parent link="hare_end_uib"/>
    <child link="hare_rubber_foot"/>
  </joint>
  <link name="hare_rubber_foot">
    <inertial>
      <origin xyz="0 0 -0.01"/>
      <mass value="1.54"/>
      <inertia ixx="0.004" ixy="0.0" ixz="0.0" iyy="0.004" iyz="0.0" izz="0.007"/>
    </inertial>
    <visual>
      <geometry>
        <mesh filename="../meshes/gltf/rubber-foot.gltf"/>
      </geometry>
    </visual>
    <collision name="hare_rubber_foot_uib_collision">
      <origin rpy="0 0 0" xyz="0 0 -0.01"/>
      <geometry>
        <cylinder length="0.05" radius="0.07"/>
      </geometry>
    </collision>
    <collision name="hare_rubber_foot_pad_collision">
      <origin rpy="0 0 0" xyz="0 0 -0.037"/>
      <geometry>
        <cylinder length="0.018" radius="0.115"/>
      </geometry>
    </collision>
  </link>
  <joint name="lion_rubber_foot_joint_fixed" type="fixed">
    <parent link="lion_end_uib"/>
    <child link="lion_rubber_foot"/>
  </joint>
  <link name="lion_rubber_foot">
    <inertial>
      <origin xyz="0 0 -0.01"/>
      <mass value="1.54"/>
      <inertia ixx="0.004" ixy="0.0" ixz="0.0" iyy="0.004" iyz="0.0" izz="0.007"/>
    </inertial>
    <visual>
      <geometry>
        <mesh filename="../meshes/gltf/rubber-foot.gltf"/>
      </geometry>
    </visual>
    <collision name="lion_rubber_foot_uib_collision">
      <origin rpy="0 0 0" xyz="0 0 -0.01"/>
      <geometry>
        <cylinder length="0.05" radius="0.07"/>
      </geometry>
    </collision>
    <collision name="lion_rubber_foot_pad_collision">
      <origin rpy="0 0 0" xyz="0 0 -0.037"/>
      <geometry>
        <cylinder length="0.018" radius="0.115"/>
      </geometry>
    </collision>
  </link>
  <joint name="pony_rubber_foot_joint_fixed" type="fixed">
    <parent link="pony_end_uib"/>
    <child link="pony_rubber_foot"/>
  </joint>
  <link name="pony_rubber_foot">
    <inertial>
      <origin xyz="0 0 -0.01"/>
      <mass value="1.54"/>
      <inertia ixx="0.004" ixy="0.0" ixz="0.0" iyy="0.004" iyz="0.0" izz="0.007"/>
    </inertial>
    <visual>
      <geometry>
        <mesh filename="../meshes/gltf/rubber-foot.gltf"/>
      </geometry>
    </visual>
    <collision name="pony_rubber_foot_uib_collision">
      <origin rpy="0 0 0" xyz="0 0 -0.01"/>
      <geometry>
        <cylinder length="0.05" radius="0.07"/>
      </geometry>
    </collision>
    <collision name="pony_rubber_foot_pad_collision">
      <origin rpy="0 0 0" xyz="0 0 -0.037"/>
      <geometry>
        <cylinder length="0.018" radius="0.115"/>
      </geometry>
    </collision>
  </link>
</robot>
