<?xml version="1.0" ?>
<!-- =================================================================================== -->
<!-- |    This document was autogenerated by xacro from XACRO/3dof-worm.urdf.xacro     | -->
<!-- |    EDITING THIS FILE BY HAND IS NOT RECOMMENDED                                 | -->
<!-- =================================================================================== -->
<robot name="worm" xmlns:drake="http://drake.mit.edu">
  <joint name="pony_uib_joint_fixed" type="fixed">
    <parent link="world"/>
    <child link="pony_base"/>
    <origin rpy="0 0 0" xyz="0 0 0"/>
  </joint>
  <link name="pony_base"/>
  <joint name="pony_base_joint_fixed" type="fixed">
    <parent link="pony_base"/>
    <child link="pony_link_0"/>
  </joint>
  <link name="pony_link_0">
    <inertial>
      <origin rpy="0 0 0" xyz="0 0 0.0725"/>
      <mass value="1.59"/>
      <inertia ixx="0.010" ixy="0" ixz="0" iyy="0.010" iyz="0" izz="0.011"/>
    </inertial>
    <visual>
      <origin rpy="0 0 0" xyz="0 0 0.045"/>
      <geometry>
        <mesh filename="../meshes/gltf/link-0.gltf"/>
      </geometry>
    </visual>
    <collision name="pony_link_0_base_collision">
      <origin rpy="0 0 0" xyz="0 0 0.035"/>
      <geometry>
        <cylinder length="0.11" radius="0.075"/>
      </geometry>
    </collision>
    <collision name="pony_link_0_motor_collision">
      <origin rpy="0 1.57 0" xyz="0.008 0 0.145"/>
      <geometry>
        <cylinder length="0.075" radius="0.06"/>
      </geometry>
    </collision>
  </link>
  <joint name="pony_joint_0" type="revolute">
    <parent link="pony_link_0"/>
    <child link="pony_link_1"/>
    <origin rpy="0 0 0" xyz="0 0 0.145"/>
    <axis xyz="1 0 0"/>
    <limit effort="120" lower="-2.094" upper="2.094" velocity="5.02654824"/>
    <dynamics damping="0.8487"/>
  </joint>
  <link name="pony_link_1">
    <inertial>
      <origin rpy="0 0 0" xyz="0 0 0.1275"/>
      <mass value="1.59"/>
      <inertia ixx="0.011" ixy="0" ixz="0" iyy="0.011" iyz="0" izz="0.004"/>
    </inertial>
    <visual>
      <origin rpy="0 0 -1.57" xyz="0.05 0 0"/>
      <geometry>
        <mesh filename="../meshes/gltf/link-1.gltf"/>
      </geometry>
    </visual>
    <collision name="pony_link_1_base_collision">
      <origin rpy="0 0 0" xyz="0.01 0 0.085"/>
      <geometry>
        <box size="0.1 0.08 0.22"/>
      </geometry>
    </collision>
    <collision name="pony_link_1_motor_collision">
      <origin rpy="1.57 0 0" xyz="0 -0.008 0.255"/>
      <geometry>
        <cylinder length="0.075" radius="0.06"/>
      </geometry>
    </collision>
  </link>
  <joint name="pony_joint_1" type="revolute">
    <parent link="pony_link_1"/>
    <child link="pony_link_2"/>
    <origin rpy="0 0 0" xyz="0 0 0.25"/>
    <axis xyz="0 1 0"/>
    <limit effort="120" lower="-2.094" upper="2.094" velocity="5.02654824"/>
    <dynamics damping="0.8487"/>
  </joint>
  <link name="pony_link_2">
    <inertial>
      <origin rpy="0 0 0" xyz="0 0 0.11"/>
      <mass value="1.59"/>
      <inertia ixx="0.009" ixy="0" ixz="0" iyy="0.009" iyz="0" izz="0.004"/>
    </inertial>
    <visual>
      <origin rpy="0 0 3.14" xyz="0 -0.05 0"/>
      <geometry>
        <mesh filename="../meshes/gltf/link-2.gltf"/>
      </geometry>
    </visual>
    <collision name="pony_link_2_base_collision">
      <origin rpy="0 0 0" xyz="0 -0.01 0.07"/>
      <geometry>
        <box size="0.08 0.1 0.18"/>
      </geometry>
    </collision>
    <collision name="pony_link_2_motor_collision">
      <origin rpy="1.57 0 0" xyz="0 -0.01 0.22"/>
      <geometry>
        <cylinder length="0.075" radius="0.06"/>
      </geometry>
    </collision>
  </link>
  <joint name="pony_joint_2" type="revolute">
    <parent link="pony_link_2"/>
    <child link="pony_link_3"/>
    <origin rpy="0 0 0" xyz="0 0 0.22"/>
    <axis xyz="0 1 0"/>
    <limit effort="120" lower="-2.094" upper="2.094" velocity="5.02654824"/>
    <dynamics damping="0.8487"/>
  </joint>
  <link name="pony_link_3">
    <inertial>
      <origin rpy="0 0 0" xyz="0 0.015 0.2425"/>
      <mass value="5.00"/>
      <inertia ixx="0.107" ixy="0" ixz="0" iyy="0.103" iyz="0" izz="0.014"/>
    </inertial>
    <visual>
      <origin rpy="0 0 1.57" xyz="0 -0.05 0"/>
      <geometry>
        <mesh filename="../meshes/gltf/link-3.gltf"/>
      </geometry>
    </visual>
    <collision name="pony_link_3_base_collision">
      <origin rpy="0 0 0" xyz="0 -0.015 0.2"/>
      <geometry>
        <box size="0.11 0.15 0.45"/>
      </geometry>
    </collision>
    <collision name="pony_link_3_uib_collision">
      <origin rpy="0 0 0" xyz="0 -0.01 0.46"/>
      <geometry>
        <cylinder length="0.08" radius="0.075"/>
      </geometry>
    </collision>
  </link>
  <!-- Downstream link -->
  <joint name="pony_end_uib_joint_fixed" type="fixed">
    <parent link="pony_link_3"/>
    <child link="pony_end_uib"/>
    <origin rpy="3.14 0 -0.35" xyz="0 -0.012 0.498"/>
  </joint>
  <link name="pony_end_uib"/>
  <!-- Transmission definitions -->
  <transmission name="pony_tran_0">
    <type>transmission_interface/SimpleTransmission</type>
    <joint name="pony_joint_0">
      <hardwareInterface>EffortJointInterface</hardwareInterface>
    </joint>
    <actuator name="pony_actuator_0">
      <mechanicalReduction>1</mechanicalReduction>
      <drake:gear_ratio value="64"/>
      <drake:rotor_inertia value="5.645e-05"/>
    </actuator>
  </transmission>
  <transmission name="pony_tran_1">
    <type>transmission_interface/SimpleTransmission</type>
    <joint name="pony_joint_1">
      <hardwareInterface>EffortJointInterface</hardwareInterface>
    </joint>
    <actuator name="pony_actuator_1">
      <mechanicalReduction>1</mechanicalReduction>
      <drake:gear_ratio value="64"/>
      <drake:rotor_inertia value="5.645e-05"/>
    </actuator>
  </transmission>
  <transmission name="pony_tran_2">
    <type>transmission_interface/SimpleTransmission</type>
    <joint name="pony_joint_2">
      <hardwareInterface>EffortJointInterface</hardwareInterface>
    </joint>
    <actuator name="pony_actuator_2">
      <mechanicalReduction>1</mechanicalReduction>
      <drake:gear_ratio value="64"/>
      <drake:rotor_inertia value="5.645e-05"/>
    </actuator>
  </transmission>
</robot>
