<?xml version="1.0" ?>
<!-- ================================================================================= -->
<!-- |    This document was autogenerated by xacro from robot.urdf.xacro             | -->
<!-- |    EDITING THIS FILE BY HAND IS NOT RECOMMENDED                               | -->
<!-- ================================================================================= -->
<robot name="rrr_description" xmlns:drake="http://drake.mit.edu">
  <!-- ================== -->
  <!--     LINK MACROS    -->
  <!-- ================== -->
  <!-- ================== -->
  <!--     JOINT MACROS   -->
  <!-- ================== -->
  <!-- ================================= -->
  <!-- |  INERTIAL PROPERTIES - LINKS  | -->
  <!-- ================================= -->
  <!-- Moon Terrain -->
  <link name="moon_terrain">
    <visual>
      <origin rpy="0 0 0" xyz="0 0 0"/>
      <geometry>
        <mesh filename="../Meshes/3d-model.obj"/>
      </geometry>
    </visual>
  </link>
  <link name="pallet">
    <visual>
      <origin rpy="-1.57 0 0" xyz="0 0 0.522"/>
      <geometry>
        <mesh filename="../Meshes/pallet.gltf"/>
      </geometry>
    </visual>
    <collision name="pallet-top-collision">
      <origin rpy="0 0 0" xyz="0 0 0.44"/>
      <geometry>
        <box size="0.45 0.80 0.25"/>
      </geometry>
    </collision>
    <collision name="pallet-bottom-collision">
      <origin rpy="0 1.57 0" xyz=" 0 0 0.20"/>
      <geometry>
        <box size="0.40 0.55 0.455"/>
      </geometry>
    </collision>
  </link>
  <!-- Arm 1 -->
  <link name="link-1.1">
    <inertial>
      <origin rpy="0 0 0" xyz="0 0 0.0725"/>
      <mass value="1.59"/>
      <inertia ixx="0.01" ixy="0" ixz="0" iyy="0.01" iyz="0" izz="0.011"/>
    </inertial>
    <visual>
      <origin rpy="-1.57 0 0" xyz="0 0 0"/>
      <geometry>
        <mesh filename="../Meshes/link-1.gltf"/>
      </geometry>
    </visual>
    <collision name="link-1-base-collision">
      <origin rpy="0 0 0" xyz="0 0 0.035"/>
      <geometry>
        <cylinder length="0.11" radius="0.075"/>
      </geometry>
    </collision>
    <collision name="link-1-motor-collision">
      <origin rpy="0 1.57 0" xyz="-0.008 0 0.145"/>
      <geometry>
        <cylinder length="0.075" radius="0.06"/>
      </geometry>
    </collision>
  </link>
  <link name="link-1.2">
    <inertial>
      <origin rpy="0 0 0" xyz="0 0 0.1275"/>
      <mass value="1.59"/>
      <inertia ixx="0.011" ixy="0" ixz="0" iyy="0.011" iyz="0" izz="0.004"/>
    </inertial>
    <visual>
      <origin rpy="-1.57 0 0" xyz="-0.009 0 0"/>
      <geometry>
        <mesh filename="../Meshes/link-2.gltf"/>
      </geometry>
    </visual>
    <collision name="link-2-base-collision">
      <origin rpy="0 0 0" xyz="-0.01 0 0.085"/>
      <geometry>
        <box size="0.1 0.08 0.22"/>
      </geometry>
    </collision>
    <collision name="link-2-motor-collision">
      <origin rpy="1.57 0 0" xyz="0 -0.008 0.255"/>
      <geometry>
        <cylinder length="0.075" radius="0.06"/>
      </geometry>
    </collision>
  </link>
  <link name="link-1.3">
    <inertial>
      <origin rpy="0 0 0" xyz="0 0 0.11"/>
      <mass value="1.59"/>
      <inertia ixx="0.009" ixy="0" ixz="0" iyy="0.009" iyz="0" izz="0.004"/>
    </inertial>
    <visual>
      <origin rpy="-1.57 0 0" xyz="0.0 -0.007 0.0 "/>
      <geometry>
        <mesh filename="../Meshes/link-3.gltf"/>
      </geometry>
    </visual>
    <collision name="link-3-base-collision">
      <origin rpy="0 0 0" xyz="0 -0.01 0.07"/>
      <geometry>
        <box size="0.08 0.1 0.18"/>
      </geometry>
    </collision>
    <collision name="link-3-motor-collision">
      <origin rpy="1.57 0 0" xyz="0 0.01 0.22"/>
      <geometry>
        <cylinder length="0.075" radius="0.06"/>
      </geometry>
    </collision>
  </link>
  <link name="link-1.4">
    <inertial>
      <origin rpy="0 0 0" xyz="0 0.015 0.2425"/>
      <mass value="5.0"/>
      <inertia ixx="0.107" ixy="0" ixz="0" iyy="0.103" iyz="0" izz="0.014"/>
    </inertial>
    <visual>
      <origin rpy="-1.57 0 -1.57" xyz="0 0.015 0 "/>
      <geometry>
        <mesh filename="../Meshes/link-4.gltf"/>
      </geometry>
    </visual>
    <collision name="link-3-base-collision">
      <origin rpy="0 0 0" xyz="0 0.015 0.2"/>
      <geometry>
        <box size="0.11 0.15 0.45"/>
      </geometry>
    </collision>
    <collision name="link-1-uib-collision">
      <origin rpy="0 0 0" xyz="0 0.015 0.46"/>
      <geometry>
        <cylinder length="0.08" radius="0.075"/>
      </geometry>
    </collision>
  </link>
  <!-- Arm 2 -->
  <link name="link-2.1">
    <inertial>
      <origin rpy="0 0 0" xyz="0 0 0.0725"/>
      <mass value="1.59"/>
      <inertia ixx="0.01" ixy="0" ixz="0" iyy="0.01" iyz="0" izz="0.011"/>
    </inertial>
    <visual>
      <origin rpy="-1.57 0 0" xyz="0 0 0"/>
      <geometry>
        <mesh filename="../Meshes/link-1.gltf"/>
      </geometry>
    </visual>
    <collision name="link-1-base-collision">
      <origin rpy="0 0 0" xyz="0 0 0.035"/>
      <geometry>
        <cylinder length="0.11" radius="0.075"/>
      </geometry>
    </collision>
    <collision name="link-1-motor-collision">
      <origin rpy="0 1.57 0" xyz="-0.008 0 0.145"/>
      <geometry>
        <cylinder length="0.075" radius="0.06"/>
      </geometry>
    </collision>
  </link>
  <link name="link-2.2">
    <inertial>
      <origin rpy="0 0 0" xyz="0 0 0.1275"/>
      <mass value="1.59"/>
      <inertia ixx="0.011" ixy="0" ixz="0" iyy="0.011" iyz="0" izz="0.004"/>
    </inertial>
    <visual>
      <origin rpy="-1.57 0 0" xyz="-0.009 0 0"/>
      <geometry>
        <mesh filename="../Meshes/link-2.gltf"/>
      </geometry>
    </visual>
    <collision name="link-2-base-collision">
      <origin rpy="0 0 0" xyz="-0.01 0 0.085"/>
      <geometry>
        <box size="0.1 0.08 0.22"/>
      </geometry>
    </collision>
    <collision name="link-2-motor-collision">
      <origin rpy="1.57 0 0" xyz="0 -0.008 0.255"/>
      <geometry>
        <cylinder length="0.075" radius="0.06"/>
      </geometry>
    </collision>
  </link>
  <link name="link-2.3">
    <inertial>
      <origin rpy="0 0 0" xyz="0 0 0.11"/>
      <mass value="1.59"/>
      <inertia ixx="0.009" ixy="0" ixz="0" iyy="0.009" iyz="0" izz="0.004"/>
    </inertial>
    <visual>
      <origin rpy="-1.57 0 0" xyz="0.0 -0.007 0.0 "/>
      <geometry>
        <mesh filename="../Meshes/link-3.gltf"/>
      </geometry>
    </visual>
    <collision name="link-3-base-collision">
      <origin rpy="0 0 0" xyz="0 -0.01 0.07"/>
      <geometry>
        <box size="0.08 0.1 0.18"/>
      </geometry>
    </collision>
    <collision name="link-3-motor-collision">
      <origin rpy="1.57 0 0" xyz="0 0.01 0.22"/>
      <geometry>
        <cylinder length="0.075" radius="0.06"/>
      </geometry>
    </collision>
  </link>
  <link name="link-2.4">
    <inertial>
      <origin rpy="0 0 0" xyz="0 0.015 0.2425"/>
      <mass value="5.0"/>
      <inertia ixx="0.107" ixy="0" ixz="0" iyy="0.103" iyz="0" izz="0.014"/>
    </inertial>
    <visual>
      <origin rpy="-1.57 0 -1.57" xyz="0 0.015 0 "/>
      <geometry>
        <mesh filename="../Meshes/link-4.gltf"/>
      </geometry>
    </visual>
    <collision name="link-3-base-collision">
      <origin rpy="0 0 0" xyz="0 0.015 0.2"/>
      <geometry>
        <box size="0.11 0.15 0.45"/>
      </geometry>
    </collision>
    <collision name="link-1-uib-collision">
      <origin rpy="0 0 0" xyz="0 0.015 0.46"/>
      <geometry>
        <cylinder length="0.08" radius="0.075"/>
      </geometry>
    </collision>
  </link>
  <!-- Arm 3 -->
  <link name="link-3.1">
    <inertial>
      <origin rpy="0 0 0" xyz="0 0 0.0725"/>
      <mass value="1.59"/>
      <inertia ixx="0.01" ixy="0" ixz="0" iyy="0.01" iyz="0" izz="0.011"/>
    </inertial>
    <visual>
      <origin rpy="-1.57 0 0" xyz="0 0 0"/>
      <geometry>
        <mesh filename="../Meshes/link-1.gltf"/>
      </geometry>
    </visual>
    <collision name="link-1-base-collision">
      <origin rpy="0 0 0" xyz="0 0 0.035"/>
      <geometry>
        <cylinder length="0.11" radius="0.075"/>
      </geometry>
    </collision>
    <collision name="link-1-motor-collision">
      <origin rpy="0 1.57 0" xyz="-0.008 0 0.145"/>
      <geometry>
        <cylinder length="0.075" radius="0.06"/>
      </geometry>
    </collision>
  </link>
  <link name="link-3.2">
    <inertial>
      <origin rpy="0 0 0" xyz="0 0 0.1275"/>
      <mass value="1.59"/>
      <inertia ixx="0.011" ixy="0" ixz="0" iyy="0.011" iyz="0" izz="0.004"/>
    </inertial>
    <visual>
      <origin rpy="-1.57 0 0" xyz="-0.009 0 0"/>
      <geometry>
        <mesh filename="../Meshes/link-2.gltf"/>
      </geometry>
    </visual>
    <collision name="link-2-base-collision">
      <origin rpy="0 0 0" xyz="-0.01 0 0.085"/>
      <geometry>
        <box size="0.1 0.08 0.22"/>
      </geometry>
    </collision>
    <collision name="link-2-motor-collision">
      <origin rpy="1.57 0 0" xyz="0 -0.008 0.255"/>
      <geometry>
        <cylinder length="0.075" radius="0.06"/>
      </geometry>
    </collision>
  </link>
  <link name="link-3.3">
    <inertial>
      <origin rpy="0 0 0" xyz="0 0 0.11"/>
      <mass value="1.59"/>
      <inertia ixx="0.009" ixy="0" ixz="0" iyy="0.009" iyz="0" izz="0.004"/>
    </inertial>
    <visual>
      <origin rpy="-1.57 0 0" xyz="0.0 -0.007 0.0 "/>
      <geometry>
        <mesh filename="../Meshes/link-3.gltf"/>
      </geometry>
    </visual>
    <collision name="link-3-base-collision">
      <origin rpy="0 0 0" xyz="0 -0.01 0.07"/>
      <geometry>
        <box size="0.08 0.1 0.18"/>
      </geometry>
    </collision>
    <collision name="link-3-motor-collision">
      <origin rpy="1.57 0 0" xyz="0 0.01 0.22"/>
      <geometry>
        <cylinder length="0.075" radius="0.06"/>
      </geometry>
    </collision>
  </link>
  <link name="link-3.4">
    <inertial>
      <origin rpy="0 0 0" xyz="0 0.015 0.2425"/>
      <mass value="5.0"/>
      <inertia ixx="0.107" ixy="0" ixz="0" iyy="0.103" iyz="0" izz="0.014"/>
    </inertial>
    <visual>
      <origin rpy="-1.57 0 -1.57" xyz="0 0.015 0 "/>
      <geometry>
        <mesh filename="../Meshes/link-4.gltf"/>
      </geometry>
    </visual>
    <collision name="link-3-base-collision">
      <origin rpy="0 0 0" xyz="0 0.015 0.2"/>
      <geometry>
        <box size="0.11 0.15 0.45"/>
      </geometry>
    </collision>
    <collision name="link-1-uib-collision">
      <origin rpy="0 0 0" xyz="0 0.015 0.46"/>
      <geometry>
        <cylinder length="0.08" radius="0.075"/>
      </geometry>
    </collision>
  </link>
  <!-- Arm 4 -->
  <link name="link-4.1">
    <inertial>
      <origin rpy="0 0 0" xyz="0 0 0.0725"/>
      <mass value="1.59"/>
      <inertia ixx="0.01" ixy="0" ixz="0" iyy="0.01" iyz="0" izz="0.011"/>
    </inertial>
    <visual>
      <origin rpy="-1.57 0 0" xyz="0 0 0"/>
      <geometry>
        <mesh filename="../Meshes/link-1.gltf"/>
      </geometry>
    </visual>
    <collision name="link-1-base-collision">
      <origin rpy="0 0 0" xyz="0 0 0.035"/>
      <geometry>
        <cylinder length="0.11" radius="0.075"/>
      </geometry>
    </collision>
    <collision name="link-1-motor-collision">
      <origin rpy="0 1.57 0" xyz="-0.008 0 0.145"/>
      <geometry>
        <cylinder length="0.075" radius="0.06"/>
      </geometry>
    </collision>
  </link>
  <link name="link-4.2">
    <inertial>
      <origin rpy="0 0 0" xyz="0 0 0.1275"/>
      <mass value="1.59"/>
      <inertia ixx="0.011" ixy="0" ixz="0" iyy="0.011" iyz="0" izz="0.004"/>
    </inertial>
    <visual>
      <origin rpy="-1.57 0 0" xyz="-0.009 0 0"/>
      <geometry>
        <mesh filename="../Meshes/link-2.gltf"/>
      </geometry>
    </visual>
    <collision name="link-2-base-collision">
      <origin rpy="0 0 0" xyz="-0.01 0 0.085"/>
      <geometry>
        <box size="0.1 0.08 0.22"/>
      </geometry>
    </collision>
    <collision name="link-2-motor-collision">
      <origin rpy="1.57 0 0" xyz="0 -0.008 0.255"/>
      <geometry>
        <cylinder length="0.075" radius="0.06"/>
      </geometry>
    </collision>
  </link>
  <link name="link-4.3">
    <inertial>
      <origin rpy="0 0 0" xyz="0 0 0.11"/>
      <mass value="1.59"/>
      <inertia ixx="0.009" ixy="0" ixz="0" iyy="0.009" iyz="0" izz="0.004"/>
    </inertial>
    <visual>
      <origin rpy="-1.57 0 0" xyz="0.0 -0.007 0.0 "/>
      <geometry>
        <mesh filename="../Meshes/link-3.gltf"/>
      </geometry>
    </visual>
    <collision name="link-3-base-collision">
      <origin rpy="0 0 0" xyz="0 -0.01 0.07"/>
      <geometry>
        <box size="0.08 0.1 0.18"/>
      </geometry>
    </collision>
    <collision name="link-3-motor-collision">
      <origin rpy="1.57 0 0" xyz="0 0.01 0.22"/>
      <geometry>
        <cylinder length="0.075" radius="0.06"/>
      </geometry>
    </collision>
  </link>
  <link name="link-4.4">
    <inertial>
      <origin rpy="0 0 0" xyz="0 0.015 0.2425"/>
      <mass value="5.0"/>
      <inertia ixx="0.107" ixy="0" ixz="0" iyy="0.103" iyz="0" izz="0.014"/>
    </inertial>
    <visual>
      <origin rpy="-1.57 0 -1.57" xyz="0 0.015 0 "/>
      <geometry>
        <mesh filename="../Meshes/link-4.gltf"/>
      </geometry>
    </visual>
    <collision name="link-3-base-collision">
      <origin rpy="0 0 0" xyz="0 0.015 0.2"/>
      <geometry>
        <box size="0.11 0.15 0.45"/>
      </geometry>
    </collision>
    <collision name="link-1-uib-collision">
      <origin rpy="0 0 0" xyz="0 0.015 0.46"/>
      <geometry>
        <cylinder length="0.08" radius="0.075"/>
      </geometry>
    </collision>
  </link>
  <!-- Arm 5 -->
  <link name="link-5.1">
    <inertial>
      <origin rpy="0 0 0" xyz="0 0 0.0725"/>
      <mass value="1.59"/>
      <inertia ixx="0.01" ixy="0" ixz="0" iyy="0.01" iyz="0" izz="0.011"/>
    </inertial>
    <visual>
      <origin rpy="-1.57 0 0" xyz="0 0 0"/>
      <geometry>
        <mesh filename="../Meshes/link-1.gltf"/>
      </geometry>
    </visual>
    <collision name="link-1-base-collision">
      <origin rpy="0 0 0" xyz="0 0 0.035"/>
      <geometry>
        <cylinder length="0.11" radius="0.075"/>
      </geometry>
    </collision>
    <collision name="link-1-motor-collision">
      <origin rpy="0 1.57 0" xyz="-0.008 0 0.145"/>
      <geometry>
        <cylinder length="0.075" radius="0.06"/>
      </geometry>
    </collision>
  </link>
  <link name="link-5.2">
    <inertial>
      <origin rpy="0 0 0" xyz="0 0 0.1275"/>
      <mass value="1.59"/>
      <inertia ixx="0.011" ixy="0" ixz="0" iyy="0.011" iyz="0" izz="0.004"/>
    </inertial>
    <visual>
      <origin rpy="-1.57 0 0" xyz="-0.009 0 0"/>
      <geometry>
        <mesh filename="../Meshes/link-2.gltf"/>
      </geometry>
    </visual>
    <collision name="link-2-base-collision">
      <origin rpy="0 0 0" xyz="-0.01 0 0.085"/>
      <geometry>
        <box size="0.1 0.08 0.22"/>
      </geometry>
    </collision>
    <collision name="link-2-motor-collision">
      <origin rpy="1.57 0 0" xyz="0 -0.008 0.255"/>
      <geometry>
        <cylinder length="0.075" radius="0.06"/>
      </geometry>
    </collision>
  </link>
  <link name="link-5.3">
    <inertial>
      <origin rpy="0 0 0" xyz="0 0 0.11"/>
      <mass value="1.59"/>
      <inertia ixx="0.009" ixy="0" ixz="0" iyy="0.009" iyz="0" izz="0.004"/>
    </inertial>
    <visual>
      <origin rpy="-1.57 0 0" xyz="0.0 -0.007 0.0 "/>
      <geometry>
        <mesh filename="../Meshes/link-3.gltf"/>
      </geometry>
    </visual>
    <collision name="link-3-base-collision">
      <origin rpy="0 0 0" xyz="0 -0.01 0.07"/>
      <geometry>
        <box size="0.08 0.1 0.18"/>
      </geometry>
    </collision>
    <collision name="link-3-motor-collision">
      <origin rpy="1.57 0 0" xyz="0 0.01 0.22"/>
      <geometry>
        <cylinder length="0.075" radius="0.06"/>
      </geometry>
    </collision>
  </link>
  <link name="link-5.4">
    <inertial>
      <origin rpy="0 0 0" xyz="0 0.015 0.2425"/>
      <mass value="5.0"/>
      <inertia ixx="0.107" ixy="0" ixz="0" iyy="0.103" iyz="0" izz="0.014"/>
    </inertial>
    <visual>
      <origin rpy="-1.57 0 -1.57" xyz="0 0.015 0 "/>
      <geometry>
        <mesh filename="../Meshes/link-4.gltf"/>
      </geometry>
    </visual>
    <collision name="link-3-base-collision">
      <origin rpy="0 0 0" xyz="0 0.015 0.2"/>
      <geometry>
        <box size="0.11 0.15 0.45"/>
      </geometry>
    </collision>
    <collision name="link-1-uib-collision">
      <origin rpy="0 0 0" xyz="0 0.015 0.46"/>
      <geometry>
        <cylinder length="0.08" radius="0.075"/>
      </geometry>
    </collision>
  </link>
  <!-- Arm 6 -->
  <link name="link-6.1">
    <inertial>
      <origin rpy="0 0 0" xyz="0 0 0.0725"/>
      <mass value="1.59"/>
      <inertia ixx="0.01" ixy="0" ixz="0" iyy="0.01" iyz="0" izz="0.011"/>
    </inertial>
    <visual>
      <origin rpy="-1.57 0 0" xyz="0 0 0"/>
      <geometry>
        <mesh filename="../Meshes/link-1.gltf"/>
      </geometry>
    </visual>
    <collision name="link-1-base-collision">
      <origin rpy="0 0 0" xyz="0 0 0.035"/>
      <geometry>
        <cylinder length="0.11" radius="0.075"/>
      </geometry>
    </collision>
    <collision name="link-1-motor-collision">
      <origin rpy="0 1.57 0" xyz="-0.008 0 0.145"/>
      <geometry>
        <cylinder length="0.075" radius="0.06"/>
      </geometry>
    </collision>
  </link>
  <link name="link-6.2">
    <inertial>
      <origin rpy="0 0 0" xyz="0 0 0.1275"/>
      <mass value="1.59"/>
      <inertia ixx="0.011" ixy="0" ixz="0" iyy="0.011" iyz="0" izz="0.004"/>
    </inertial>
    <visual>
      <origin rpy="-1.57 0 0" xyz="-0.009 0 0"/>
      <geometry>
        <mesh filename="../Meshes/link-2.gltf"/>
      </geometry>
    </visual>
    <collision name="link-2-base-collision">
      <origin rpy="0 0 0" xyz="-0.01 0 0.085"/>
      <geometry>
        <box size="0.1 0.08 0.22"/>
      </geometry>
    </collision>
    <collision name="link-2-motor-collision">
      <origin rpy="1.57 0 0" xyz="0 -0.008 0.255"/>
      <geometry>
        <cylinder length="0.075" radius="0.06"/>
      </geometry>
    </collision>
  </link>
  <link name="link-6.3">
    <inertial>
      <origin rpy="0 0 0" xyz="0 0 0.11"/>
      <mass value="1.59"/>
      <inertia ixx="0.009" ixy="0" ixz="0" iyy="0.009" iyz="0" izz="0.004"/>
    </inertial>
    <visual>
      <origin rpy="-1.57 0 0" xyz="0.0 -0.007 0.0 "/>
      <geometry>
        <mesh filename="../Meshes/link-3.gltf"/>
      </geometry>
    </visual>
    <collision name="link-3-base-collision">
      <origin rpy="0 0 0" xyz="0 -0.01 0.07"/>
      <geometry>
        <box size="0.08 0.1 0.18"/>
      </geometry>
    </collision>
    <collision name="link-3-motor-collision">
      <origin rpy="1.57 0 0" xyz="0 0.01 0.22"/>
      <geometry>
        <cylinder length="0.075" radius="0.06"/>
      </geometry>
    </collision>
  </link>
  <link name="link-6.4">
    <inertial>
      <origin rpy="0 0 0" xyz="0 0.015 0.2425"/>
      <mass value="5.0"/>
      <inertia ixx="0.107" ixy="0" ixz="0" iyy="0.103" iyz="0" izz="0.014"/>
    </inertial>
    <visual>
      <origin rpy="-1.57 0 -1.57" xyz="0 0.015 0 "/>
      <geometry>
        <mesh filename="../Meshes/link-4.gltf"/>
      </geometry>
    </visual>
    <collision name="link-3-base-collision">
      <origin rpy="0 0 0" xyz="0 0.015 0.2"/>
      <geometry>
        <box size="0.11 0.15 0.45"/>
      </geometry>
    </collision>
    <collision name="link-1-uib-collision">
      <origin rpy="0 0 0" xyz="0 0.015 0.46"/>
      <geometry>
        <cylinder length="0.08" radius="0.075"/>
      </geometry>
    </collision>
  </link>

<!-- Foot  -->

  <link name="foot-1">
    <inertial>
      <origin rpy="0 0 0" xyz="0 0 0.0725"/>
      <mass value="1.06"/>
      <inertia ixx="0.044" ixy="0" ixz="0" iyy="0.044" iyz="0" izz="0.085"/>
    </inertial>
    <visual>
      <origin rpy="-1.57 0 0" xyz="0 0 0"/>
      <geometry>
        <mesh filename="../Meshes/foot.gltf"/>
      </geometry>
    </visual>
    <collision name="foot-1-collision">
      <origin rpy="0 0 0" xyz="0 0 0"/>
      <geometry>
        <cylinder length="0.07" radius="0.125"/>
      </geometry>
    </collision>
  </link>

  <link name="foot-2">
    <inertial>
      <origin rpy="0 0 0" xyz="0 0 0.0725"/>
      <mass value="1.06"/>
      <inertia ixx="0.044" ixy="0" ixz="0" iyy="0.044" iyz="0" izz="0.085"/>
    </inertial>
    <visual>
      <origin rpy="-1.57 0 0" xyz="0 0 0"/>
      <geometry>
        <mesh filename="../Meshes/foot.gltf"/>
      </geometry>
    </visual>
    <collision name="foot-2-collision">
      <origin rpy="0 0 0" xyz="0 0 0"/>
      <geometry>
        <cylinder length="0.07" radius="0.125"/>
      </geometry>
    </collision>
  </link>

  <link name="foot-3">
    <inertial>
      <origin rpy="0 0 0" xyz="0 0 0.0725"/>
      <mass value="1.06"/>
      <inertia ixx="0.044" ixy="0" ixz="0" iyy="0.044" iyz="0" izz="0.085"/>
    </inertial>
    <visual>
      <origin rpy="-1.57 0 0" xyz="0 0 0"/>
      <geometry>
        <mesh filename="../Meshes/foot.gltf"/>
      </geometry>
    </visual>
    <collision name="foot-3-collision">
      <origin rpy="0 0 0" xyz="0 0 0"/>
      <geometry>
        <cylinder length="0.07" radius="0.125"/>
      </geometry>
    </collision>
  </link>


  <link name="foot-4">
    <inertial>
      <origin rpy="0 0 0" xyz="0 0 0.0725"/>
      <mass value="1.06"/>
      <inertia ixx="0.044" ixy="0" ixz="0" iyy="0.044" iyz="0" izz="0.085"/>
    </inertial>
    <visual>
      <origin rpy="-1.57 0 0" xyz="0 0 0"/>
      <geometry>
        <mesh filename="../Meshes/foot.gltf"/>
      </geometry>
    </visual>
    <collision name="foot-4-collision">
      <origin rpy="0 0 0" xyz="0 0 0"/>
      <geometry>
        <cylinder length="0.07" radius="0.125"/>
      </geometry>
    </collision>
  </link>

  <link name="foot-5">
    <inertial>
      <origin rpy="0 0 0" xyz="0 0 0.0725"/>
      <mass value="1.06"/>
      <inertia ixx="0.044" ixy="0" ixz="0" iyy="0.044" iyz="0" izz="0.085"/>
    </inertial>
    <visual>
      <origin rpy="-1.57 0 0" xyz="0 0 0"/>
      <geometry>
        <mesh filename="../Meshes/foot.gltf"/>
      </geometry>
    </visual>
    <collision name="foot-5-collision">
      <origin rpy="0 0 0" xyz="0 0 0"/>
      <geometry>
        <cylinder length="0.07" radius="0.125"/>
      </geometry>
    </collision>
  </link>

  <link name="foot-6">
    <inertial>
      <origin rpy="0 0 0" xyz="0 0 0.0725"/>
      <mass value="1.06"/>
      <inertia ixx="0.044" ixy="0" ixz="0" iyy="0.044" iyz="0" izz="0.085"/>
    </inertial>
    <visual>
      <origin rpy="-1.57 0 0" xyz="0 0 0"/>
      <geometry>
        <mesh filename="../Meshes/foot.gltf"/>
      </geometry>
    </visual>
    <collision name="foot-6-collision">
      <origin rpy="0 0 0" xyz="0 0 0"/>
      <geometry>
        <cylinder length="0.07" radius="0.125"/>
      </geometry>
    </collision>
  </link>

  <!-- ================================= -->
  <!-- | KINEMATIC PROPERTIES - JOINTS | -->
  <!-- ================================= -->
  <joint name="pallet-moon" type="fixed">
    <parent link="moon_terrain"/>
    <child link="pallet"/>
    <origin rpy="0 0 0" xyz="0 0 0"/>
  </joint>
  <!-- Arm 1 -->
  <joint name="joint-1.1" type="revolute">
    <parent link="link-1.1"/>
    <child link="link-1.2"/>
    <axis xyz="1 0 0"/>
    <origin rpy="0 0 0" xyz="0 0 0.145"/>
    <limit effort="120" lower="-1.57" upper="1.57" velocity="5.02654824"/>
    <dynamics damping="0.8487"/>
  </joint>
  <joint name="joint-1.2" type="revolute">
    <parent link="link-1.2"/>
    <child link="link-1.3"/>
    <axis xyz="0 1 0"/>
    <origin rpy="0 0 0" xyz="0 0 0.255"/>
    <limit effort="120" lower="-2.094" upper="2.094" velocity="5.02654824"/>
    <dynamics damping="0.8487"/>
  </joint>
  <joint name="joint-1.3" type="revolute">
    <parent link="link-1.3"/>
    <child link="link-1.4"/>
    <axis xyz="0 1 0"/>
    <origin rpy="0 0 0" xyz="0 0 0.22"/>
    <limit effort="120" lower="-2.094" upper="2.094" velocity="5.02654824"/>
    <dynamics damping="0.8487"/>
  </joint>
  <joint name="pallet-joint1" type="fixed">
    <parent link="pallet"/>
    <child link="link-1.1"/>
    <origin rpy="0 1.57 0" xyz="0.17 0.33 0.487"/>
  </joint>
  <!-- Arm 2 -->
  <joint name="joint-2.1" type="revolute">
    <parent link="link-2.1"/>
    <child link="link-2.2"/>
    <axis xyz="1 0 0"/>
    <origin rpy="0 0 0" xyz="0 0 0.145"/>
    <limit effort="120" lower="-1.57" upper="1.57" velocity="5.02654824"/>
    <dynamics damping="0.8487"/>
  </joint>
  <joint name="joint-2.2" type="revolute">
    <parent link="link-2.2"/>
    <child link="link-2.3"/>
    <axis xyz="0 1 0"/>
    <origin rpy="0 0 0" xyz="0 0 0.255"/>
    <limit effort="120" lower="-2.094" upper="2.094" velocity="5.02654824"/>
    <dynamics damping="0.8487"/>
  </joint>
  <joint name="joint-2.3" type="revolute">
    <parent link="link-2.3"/>
    <child link="link-2.4"/>
    <axis xyz="0 1 0"/>
    <origin rpy="0 0 0" xyz="0 0 0.22"/>
    <limit effort="120" lower="-2.094" upper="2.094" velocity="5.02654824"/>
    <dynamics damping="0.8487"/>
  </joint>
  <joint name="pallet-joint2" type="fixed">
    <parent link="pallet"/>
    <child link="link-2.1"/>
    <origin rpy="0 1.57 0" xyz="0.17 -0.33 0.487"/>
  </joint>
  <!-- Arm 3 -->
  <joint name="joint-3.1" type="revolute">
    <parent link="link-3.1"/>
    <child link="link-3.2"/>
    <axis xyz="1 0 0"/>
    <origin rpy="0 0 0" xyz="0 0 0.145"/>
    <limit effort="120" lower="-1.57" upper="1.57" velocity="5.02654824"/>
    <dynamics damping="0.8487"/>
  </joint>
  <joint name="joint-3.2" type="revolute">
    <parent link="link-3.2"/>
    <child link="link-3.3"/>
    <axis xyz="0 1 0"/>
    <origin rpy="0 0 0" xyz="0 0 0.255"/>
    <limit effort="120" lower="-2.094" upper="2.094" velocity="5.02654824"/>
    <dynamics damping="0.8487"/>
  </joint>
  <joint name="joint-3.3" type="revolute">
    <parent link="link-3.3"/>
    <child link="link-3.4"/>
    <axis xyz="0 1 0"/>
    <origin rpy="0 0 0" xyz="0 0 0.22"/>
    <limit effort="120" lower="-2.094" upper="2.094" velocity="5.02654824"/>
    <dynamics damping="0.8487"/>
  </joint>
  <joint name="pallet-joint3" type="fixed">
    <parent link="pallet"/>
    <child link="link-3.1"/>
    <origin rpy="0 -1.57 0" xyz="-0.17 -0.33 0.487"/>
  </joint>
  <!-- Arm 4 -->
  <joint name="joint-4.1" type="revolute">
    <parent link="link-4.1"/>
    <child link="link-4.2"/>
    <axis xyz="1 0 0"/>
    <origin rpy="0 0 0" xyz="0 0 0.145"/>
    <limit effort="120" lower="-1.57" upper="1.57" velocity="5.02654824"/>
    <dynamics damping="0.8487"/>
  </joint>
  <joint name="joint-4.2" type="revolute">
    <parent link="link-4.2"/>
    <child link="link-4.3"/>
    <axis xyz="0 1 0"/>
    <origin rpy="0 0 0" xyz="0 0 0.255"/>
    <limit effort="120" lower="-2.094" upper="2.094" velocity="5.02654824"/>
    <dynamics damping="0.8487"/>
  </joint>
  <joint name="joint-4.3" type="revolute">
    <parent link="link-4.3"/>
    <child link="link-4.4"/>
    <axis xyz="0 1 0"/>
    <origin rpy="0 0 0" xyz="0 0 0.22"/>
    <limit effort="120" lower="-2.094" upper="2.094" velocity="5.02654824"/>
    <dynamics damping="0.8487"/>
  </joint>
  <joint name="pallet-joint4" type="fixed">
    <parent link="pallet"/>
    <child link="link-4.1"/>
    <origin rpy="0 -1.57 0" xyz="-0.17 0.33 0.487"/>
  </joint>
  <!-- Arm 5 -->
  <joint name="joint-5.1" type="revolute">
    <parent link="link-5.1"/>
    <child link="link-5.2"/>
    <axis xyz="1 0 0"/>
    <origin rpy="0 0 0" xyz="0 0 0.145"/>
    <limit effort="120" lower="-1.57" upper="1.57" velocity="5.02654824"/>
    <dynamics damping="0.8487"/>
  </joint>
  <joint name="joint-5.2" type="revolute">
    <parent link="link-5.2"/>
    <child link="link-5.3"/>
    <axis xyz="0 1 0"/>
    <origin rpy="0 0 0" xyz="0 0 0.255"/>
    <limit effort="120" lower="-2.094" upper="2.094" velocity="5.02654824"/>
    <dynamics damping="0.8487"/>
  </joint>
  <joint name="joint-5.3" type="revolute">
    <parent link="link-5.3"/>
    <child link="link-5.4"/>
    <axis xyz="0 1 0"/>
    <origin rpy="0 0 0" xyz="0 0 0.22"/>
    <limit effort="120" lower="-2.094" upper="2.094" velocity="5.02654824"/>
    <dynamics damping="0.8487"/>
  </joint>
  <joint name="pallet-joint5" type="fixed">
    <parent link="pallet"/>
    <child link="link-5.1"/>
    <origin rpy="-1.57 -1.57 0" xyz="0 0.36 0.487"/>
  </joint>
  <!-- Arm 6 -->
  <joint name="joint-6.1" type="revolute">
    <parent link="link-6.1"/>
    <child link="link-6.2"/>
    <axis xyz="1 0 0"/>
    <origin rpy="0 0 0" xyz="0 0 0.145"/>
    <limit effort="120" lower="-1.57" upper="1.57" velocity="5.02654824"/>
    <dynamics damping="0.8487"/>
  </joint>
  <joint name="joint-6.2" type="revolute">
    <parent link="link-6.2"/>
    <child link="link-6.3"/>
    <axis xyz="0 1 0"/>
    <origin rpy="0 0 0" xyz="0 0 0.255"/>
    <limit effort="120" lower="-2.094" upper="2.094" velocity="5.02654824"/>
    <dynamics damping="0.8487"/>
  </joint>
  <joint name="joint-6.3" type="revolute">
    <parent link="link-6.3"/>
    <child link="link-6.4"/>
    <axis xyz="0 1 0"/>
    <origin rpy="0 0 0" xyz="0 0 0.22"/>
    <limit effort="120" lower="-2.094" upper="2.094" velocity="5.02654824"/>
    <dynamics damping="0.8487"/>
  </joint>
  <joint name="pallet-joint6" type="fixed">
    <parent link="pallet"/>
    <child link="link-6.1"/>
    <origin rpy="1.57 1.57 0" xyz="0 -0.36 0.487"/>
  </joint>

  <joint name="foot-joint1" type="fixed">
    <parent link="link-1.4"/>
    <child link="foot-1"/>
    <origin rpy="0 3.14 0" xyz="0 0.025 0.50"/>
  </joint>

  <joint name="foot-joint2" type="fixed">
    <parent link="link-2.4"/>
    <child link="foot-2"/>
    <origin rpy="0 3.14 0" xyz="0 0.025 0.50"/>
  </joint>

  <joint name="foot-joint3" type="fixed">
    <parent link="link-3.4"/>
    <child link="foot-3"/>
    <origin rpy="0 3.14 0" xyz="0 0.025 0.50"/>
  </joint>

  <joint name="foot-joint4" type="fixed">
    <parent link="link-4.4"/>
    <child link="foot-4"/>
    <origin rpy="0 3.14 0" xyz="0 0.025 0.50"/>
  </joint>

  <joint name="foot-joint5" type="fixed">
    <parent link="link-5.4"/>
    <child link="foot-5"/>
    <origin rpy="0 3.14 0" xyz="0 0.025 0.50"/>
  </joint>

  <joint name="foot-joint6" type="fixed">
    <parent link="link-6.4"/>
    <child link="foot-6"/>
    <origin rpy="0 3.14 0" xyz="0 0.025 0.50"/>
  </joint>

  <!-- ================================= -->
  <!-- | TRANSMISSIONS  | -->
  <!-- ================================= -->
  <!-- Use the macro to create transmissions for the joints and actuators -->
  <transmission name="tran-1.1">
    <robotNamespace>/3DOF-WORM</robotNamespace>
    <type>transmission_interface/SimpleTransmission</type>
    <joint name="joint-1.1">
      <hardwareInterface>PositionJointInterface</hardwareInterface>
    </joint>
    <actuator name="motor-1.1">
      <hardwareInterface>PositionJointInterface</hardwareInterface>
      <mechanicalReduction>1</mechanicalReduction>
      <drake:gear_ratio value="64.0"/>
      <drake:rotor_inertia value="0.00005645"/>
    </actuator>
  </transmission>
  <transmission name="tran-1.2">
    <robotNamespace>/3DOF-WORM</robotNamespace>
    <type>transmission_interface/SimpleTransmission</type>
    <joint name="joint-1.2">
      <hardwareInterface>PositionJointInterface</hardwareInterface>
    </joint>
    <actuator name="motor-1.2">
      <hardwareInterface>PositionJointInterface</hardwareInterface>
      <mechanicalReduction>1</mechanicalReduction>
      <drake:gear_ratio value="64.0"/>
      <drake:rotor_inertia value="0.00005645"/>
    </actuator>
  </transmission>
  <transmission name="tran-1.3">
    <robotNamespace>/3DOF-WORM</robotNamespace>
    <type>transmission_interface/SimpleTransmission</type>
    <joint name="joint-1.3">
      <hardwareInterface>PositionJointInterface</hardwareInterface>
    </joint>
    <actuator name="motor-1.3">
      <hardwareInterface>PositionJointInterface</hardwareInterface>
      <mechanicalReduction>1</mechanicalReduction>
      <drake:gear_ratio value="64.0"/>
      <drake:rotor_inertia value="0.00005645"/>
    </actuator>
  </transmission>
  <transmission name="tran-2.1">
    <robotNamespace>/3DOF-WORM</robotNamespace>
    <type>transmission_interface/SimpleTransmission</type>
    <joint name="joint-2.1">
      <hardwareInterface>PositionJointInterface</hardwareInterface>
    </joint>
    <actuator name="motor-2.1">
      <hardwareInterface>PositionJointInterface</hardwareInterface>
      <mechanicalReduction>1</mechanicalReduction>
      <drake:gear_ratio value="64.0"/>
      <drake:rotor_inertia value="0.00005645"/>
    </actuator>
  </transmission>
  <transmission name="tran-2.2">
    <robotNamespace>/3DOF-WORM</robotNamespace>
    <type>transmission_interface/SimpleTransmission</type>
    <joint name="joint-2.2">
      <hardwareInterface>PositionJointInterface</hardwareInterface>
    </joint>
    <actuator name="motor-2.2">
      <hardwareInterface>PositionJointInterface</hardwareInterface>
      <mechanicalReduction>1</mechanicalReduction>
      <drake:gear_ratio value="64.0"/>
      <drake:rotor_inertia value="0.00005645"/>
    </actuator>
  </transmission>
  <transmission name="tran-2.3">
    <robotNamespace>/3DOF-WORM</robotNamespace>
    <type>transmission_interface/SimpleTransmission</type>
    <joint name="joint-2.3">
      <hardwareInterface>PositionJointInterface</hardwareInterface>
    </joint>
    <actuator name="motor-2.3">
      <hardwareInterface>PositionJointInterface</hardwareInterface>
      <mechanicalReduction>1</mechanicalReduction>
      <drake:gear_ratio value="64.0"/>
      <drake:rotor_inertia value="0.00005645"/>
    </actuator>
  </transmission>
  <transmission name="tran-3.1">
    <robotNamespace>/3DOF-WORM</robotNamespace>
    <type>transmission_interface/SimpleTransmission</type>
    <joint name="joint-3.1">
      <hardwareInterface>PositionJointInterface</hardwareInterface>
    </joint>
    <actuator name="motor-3.1">
      <hardwareInterface>PositionJointInterface</hardwareInterface>
      <mechanicalReduction>1</mechanicalReduction>
      <drake:gear_ratio value="64.0"/>
      <drake:rotor_inertia value="0.00005645"/>
    </actuator>
  </transmission>
  <transmission name="tran-3.2">
    <robotNamespace>/3DOF-WORM</robotNamespace>
    <type>transmission_interface/SimpleTransmission</type>
    <joint name="joint-3.2">
      <hardwareInterface>PositionJointInterface</hardwareInterface>
    </joint>
    <actuator name="motor-3.2">
      <hardwareInterface>PositionJointInterface</hardwareInterface>
      <mechanicalReduction>1</mechanicalReduction>
      <drake:gear_ratio value="64.0"/>
      <drake:rotor_inertia value="0.00005645"/>
    </actuator>
  </transmission>
  <transmission name="tran-3.3">
    <robotNamespace>/3DOF-WORM</robotNamespace>
    <type>transmission_interface/SimpleTransmission</type>
    <joint name="joint-3.3">
      <hardwareInterface>PositionJointInterface</hardwareInterface>
    </joint>
    <actuator name="motor-3.3">
      <hardwareInterface>PositionJointInterface</hardwareInterface>
      <mechanicalReduction>1</mechanicalReduction>
      <drake:gear_ratio value="64.0"/>
      <drake:rotor_inertia value="0.00005645"/>
    </actuator>
  </transmission>
  <transmission name="tran-4.1">
    <robotNamespace>/3DOF-WORM</robotNamespace>
    <type>transmission_interface/SimpleTransmission</type>
    <joint name="joint-4.1">
      <hardwareInterface>PositionJointInterface</hardwareInterface>
    </joint>
    <actuator name="motor-4.1">
      <hardwareInterface>PositionJointInterface</hardwareInterface>
      <mechanicalReduction>1</mechanicalReduction>
      <drake:gear_ratio value="64.0"/>
      <drake:rotor_inertia value="0.00005645"/>
    </actuator>
  </transmission>
  <transmission name="tran-4.2">
    <robotNamespace>/3DOF-WORM</robotNamespace>
    <type>transmission_interface/SimpleTransmission</type>
    <joint name="joint-4.2">
      <hardwareInterface>PositionJointInterface</hardwareInterface>
    </joint>
    <actuator name="motor-4.2">
      <hardwareInterface>PositionJointInterface</hardwareInterface>
      <mechanicalReduction>1</mechanicalReduction>
      <drake:gear_ratio value="64.0"/>
      <drake:rotor_inertia value="0.00005645"/>
    </actuator>
  </transmission>
  <transmission name="tran-4.3">
    <robotNamespace>/3DOF-WORM</robotNamespace>
    <type>transmission_interface/SimpleTransmission</type>
    <joint name="joint-4.3">
      <hardwareInterface>PositionJointInterface</hardwareInterface>
    </joint>
    <actuator name="motor-4.3">
      <hardwareInterface>PositionJointInterface</hardwareInterface>
      <mechanicalReduction>1</mechanicalReduction>
      <drake:gear_ratio value="64.0"/>
      <drake:rotor_inertia value="0.00005645"/>
    </actuator>
  </transmission>
  <transmission name="tran-5.1">
    <robotNamespace>/3DOF-WORM</robotNamespace>
    <type>transmission_interface/SimpleTransmission</type>
    <joint name="joint-5.1">
      <hardwareInterface>PositionJointInterface</hardwareInterface>
    </joint>
    <actuator name="motor-5.1">
      <hardwareInterface>PositionJointInterface</hardwareInterface>
      <mechanicalReduction>1</mechanicalReduction>
      <drake:gear_ratio value="64.0"/>
      <drake:rotor_inertia value="0.00005645"/>
    </actuator>
  </transmission>
  <transmission name="tran-5.2">
    <robotNamespace>/3DOF-WORM</robotNamespace>
    <type>transmission_interface/SimpleTransmission</type>
    <joint name="joint-5.2">
      <hardwareInterface>PositionJointInterface</hardwareInterface>
    </joint>
    <actuator name="motor-5.2">
      <hardwareInterface>PositionJointInterface</hardwareInterface>
      <mechanicalReduction>1</mechanicalReduction>
      <drake:gear_ratio value="64.0"/>
      <drake:rotor_inertia value="0.00005645"/>
    </actuator>
  </transmission>
  <transmission name="tran-5.3">
    <robotNamespace>/3DOF-WORM</robotNamespace>
    <type>transmission_interface/SimpleTransmission</type>
    <joint name="joint-5.3">
      <hardwareInterface>PositionJointInterface</hardwareInterface>
    </joint>
    <actuator name="motor-5.3">
      <hardwareInterface>PositionJointInterface</hardwareInterface>
      <mechanicalReduction>1</mechanicalReduction>
      <drake:gear_ratio value="64.0"/>
      <drake:rotor_inertia value="0.00005645"/>
    </actuator>
  </transmission>
  <transmission name="tran-6.1">
    <robotNamespace>/3DOF-WORM</robotNamespace>
    <type>transmission_interface/SimpleTransmission</type>
    <joint name="joint-6.1">
      <hardwareInterface>PositionJointInterface</hardwareInterface>
    </joint>
    <actuator name="motor-6.1">
      <hardwareInterface>PositionJointInterface</hardwareInterface>
      <mechanicalReduction>1</mechanicalReduction>
      <drake:gear_ratio value="64.0"/>
      <drake:rotor_inertia value="0.00005645"/>
    </actuator>
  </transmission>
  <transmission name="tran-6.2">
    <robotNamespace>/3DOF-WORM</robotNamespace>
    <type>transmission_interface/SimpleTransmission</type>
    <joint name="joint-6.2">
      <hardwareInterface>PositionJointInterface</hardwareInterface>
    </joint>
    <actuator name="motor-6.2">
      <hardwareInterface>PositionJointInterface</hardwareInterface>
      <mechanicalReduction>1</mechanicalReduction>
      <drake:gear_ratio value="64.0"/>
      <drake:rotor_inertia value="0.00005645"/>
    </actuator>
  </transmission>
  <transmission name="tran-6.3">
    <robotNamespace>/3DOF-WORM</robotNamespace>
    <type>transmission_interface/SimpleTransmission</type>
    <joint name="joint-6.3">
      <hardwareInterface>PositionJointInterface</hardwareInterface>
    </joint>
    <actuator name="motor-6.3">
      <hardwareInterface>PositionJointInterface</hardwareInterface>
      <mechanicalReduction>1</mechanicalReduction>
      <drake:gear_ratio value="64.0"/>
      <drake:rotor_inertia value="0.00005645"/>
    </actuator>
  </transmission>
</robot>
