<?xml version="1.0" ?>
<!-- =================================================================================== -->
<!-- |    This document was autogenerated by xacro from /workspace/xacro_files/robot.urdf.xacro | -->
<!-- |    EDITING THIS FILE BY HAND IS NOT RECOMMENDED                                 | -->
<!-- =================================================================================== -->
<robot name="rrr_description">
  <!-- ================== -->
  <!--     LINK MACROS    -->
  <!-- ================== -->
  <!-- ================== -->
  <!--     JOINT MACROS   -->
  <!-- ================== -->
  <!-- Properties -->
  <!-- ================================= -->
  <!-- |  INERTIAL PROPERTIES - LINKS  | -->
  <!-- ================================= -->

    <!-- New link for moon terrain -->
  <link name="moon_terrain">
    <visual>
      <origin rpy="0 0 0" xyz="0 0 0"/> <!-- Adjust position as needed -->
      <geometry>
        <mesh filename="../Meshes/3d-model.obj"/>
      </geometry>
    </visual>
  </link>

  <link name="link-1">
    <visual>
      <origin rpy="-1.57 0 0" xyz="0 0 0"/>
      <geometry>
        <mesh filename="../Meshes/link-1.obj"/>
      </geometry>
    </visual>
  </link>
  <link name="link-2">
    <visual>
      <origin rpy="-1.57 0 0" xyz="-0.009 0 0"/>
      <geometry>
        <mesh filename="../Meshes/link-2.obj"/>
      </geometry>
    </visual>
  </link>
  <link name="link-3">
    <visual>
      <origin rpy="1.57 3.14 0" xyz="0.0 -0.007 0.0 "/>
      <geometry>
        <mesh filename="../Meshes/link-3.obj"/>
      </geometry>
    </visual>
  </link>
  <link name="link-4">
    <visual>
      <origin rpy="-1.57 0 -1.57" xyz="0 0.015 0 "/>
      <geometry>
        <mesh filename="../Meshes/link-4.obj"/>
      </geometry>
    </visual>
  </link>
  <link name="pallet">
    <visual>
      <origin rpy="-1.57 0 0" xyz="0 0 0.522"/>
      <geometry>
        <mesh filename="../Meshes/pallet.gltf"/>
      </geometry>
    </visual>
  </link>

  <!-- ================================= -->
  <!-- | KINEMATIC PROPERTIES - JOINTS | -->
  <!-- ================================= -->

  <!-- Add a joint to fix the terrain to the world (optional) -->
  <joint name="moon_terrain_joint" type="fixed">
    <parent link="world"/>
    <child link="moon_terrain"/>
    <origin rpy="0 0 0" xyz="0 0 0"/>
  </joint>
  
  <joint name="link1_joint" type="revolute">
    <parent link="link-1"/>
    <child link="link-2"/>
    <axis xyz="1 0 0"/>
    <origin rpy="0 0 0" xyz="0 0 0.1004"/>
    <limit effort="120" lower="-1.57" upper="1.57" velocity="5.02654824"/>
    <dynamics damping="1"/>
  </joint>
  <joint name="link2_joint" type="revolute">
    <parent link="link-2"/>
    <child link="link-3"/>
    <axis xyz="0 1 0"/>
    <origin rpy="0 0 0" xyz="0 0 0.255"/>
    <limit effort="120" lower="-2.094" upper="2.094" velocity="5.02654824"/>
    <dynamics damping="1"/>
  </joint>
  <joint name="link3_joint" type="revolute">
    <parent link="link-3"/>
    <child link="link-4"/>
    <axis xyz="0 1 0"/>
    <origin rpy="0 0 0" xyz="0 0 0.22"/>
    <limit effort="120" lower="-2.094" upper="2.094" velocity="5.02654824"/>
    <dynamics damping="1"/>
  </joint>
  <joint name="pallet_joint" type="fixed">
    <parent link="pallet"/>
    <child link="link-1"/>
    <origin rpy="0 1.57 0" xyz="0.234 0.33 0.487"/>
  </joint>
</robot>